2023-06-05 21:52:49 INFO:     Will watch for changes in these directories: ['/']
2023-06-05 21:52:49 INFO:     Uvicorn running on http://0.0.0.0:8083 (Press CTRL+C to quit)
2023-06-05 21:52:49 INFO:     Started reloader process [1] using WatchFiles
2023-06-05 21:52:50 INFO:     Started server process [9]
2023-06-05 21:52:50 INFO:     Waiting for application startup.
2023-06-05 21:52:50 INFO:     Application startup complete.
2023-06-05 21:52:51 WARNING:root:Circuit "get_author" is "closed", failures: 0
2023-06-05 21:52:51 WARNING:root:
2023-06-05 21:52:52 WARNING:root:Circuit "get_author" is "closed", failures: 0
2023-06-05 21:52:52 WARNING:root:
2023-06-05 21:52:53 WARNING:root:Circuit "get_author" is "closed", failures: 0
2023-06-05 21:52:53 WARNING:root:
2023-06-05 21:52:54 WARNING:root:Circuit "get_author" is "closed", failures: 0
2023-06-05 21:52:54 WARNING:root:
2023-06-05 21:52:55 WARNING:root:Circuit "get_author" is "closed", failures: 0
2023-06-05 21:52:55 WARNING:root:
2023-06-05 21:52:56 WARNING:root:Circuit "get_author" is "closed", failures: 0
2023-06-05 21:52:56 WARNING:root:
2023-06-05 21:52:57 WARNING:root:Circuit "get_author" is "closed", failures: 0
2023-06-05 21:52:57 WARNING:root:
2023-06-05 21:52:58 WARNING:root:Circuit "get_author" is "closed", failures: 0
2023-06-05 21:52:58 WARNING:root:
2023-06-05 21:52:59 WARNING:root:Circuit "get_author" is "closed", failures: 0
2023-06-05 21:52:59 WARNING:root:
2023-06-05 21:53:00 WARNING:root:Circuit "get_author" is "closed", failures: 0
2023-06-05 21:53:00 WARNING:root:
2023-06-05 21:53:01 WARNING:root:Circuit "get_author" is "closed", failures: 0
2023-06-05 21:53:01 WARNING:root:
2023-06-05 21:53:02 WARNING:root:Circuit "get_author" is "closed", failures: 0
2023-06-05 21:53:03 WARNING:root:
2023-06-05 21:53:04 WARNING:root:Circuit "get_author" is "closed", failures: 0
2023-06-05 21:53:04 WARNING:root:
2023-06-05 21:53:05 WARNING:root:Circuit "get_author" is "closed", failures: 0
2023-06-05 21:53:05 WARNING:root:
2023-06-05 21:53:06 WARNING:root:Circuit "get_author" is "closed", failures: 0
2023-06-05 21:53:06 WARNING:root:
2023-06-05 21:53:07 WARNING:root:Circuit "get_author" is "closed", failures: 0
2023-06-05 21:53:07 WARNING:root:
2023-06-05 21:53:08 WARNING:root:Circuit "get_author" is "closed", failures: 0
2023-06-05 21:53:08 WARNING:root:
2023-06-05 21:53:09 WARNING:root:Circuit "get_author" is "closed", failures: 0
2023-06-05 21:53:09 WARNING:root:
2023-06-05 21:53:10 WARNING:root:Circuit "get_author" is "closed", failures: 0
2023-06-05 21:53:10 WARNING:root:
2023-06-05 21:53:11 WARNING:root:Circuit "get_author" is "closed", failures: 0
2023-06-05 21:53:11 WARNING:root:
2023-06-05 21:53:12 WARNING:root:Circuit "get_author" is "closed", failures: 0
2023-06-05 21:53:12 WARNING:root:
2023-06-05 21:53:13 WARNING:root:Circuit "get_author" is "closed", failures: 0
2023-06-05 21:53:13 WARNING:root:
2023-06-05 21:53:14 WARNING:root:Circuit "get_author" is "closed", failures: 0
2023-06-05 21:53:14 WARNING:root:
2023-06-05 21:53:15 WARNING:root:Circuit "get_author" is "closed", failures: 0
2023-06-05 21:53:15 WARNING:root:
2023-06-05 21:53:16 WARNING:root:Circuit "get_author" is "closed", failures: 0
2023-06-05 21:53:16 WARNING:root:
2023-06-05 21:53:17 WARNING:root:Circuit "get_author" is "closed", failures: 0
2023-06-05 21:53:17 WARNING:root:
2023-06-05 21:53:18 WARNING:root:Circuit "get_author" is "closed", failures: 0
2023-06-05 21:53:18 WARNING:root:
2023-06-05 21:53:19 WARNING:root:Circuit "get_author" is "closed", failures: 0
2023-06-05 21:53:19 WARNING:root:
2023-06-05 21:53:20 WARNING:root:Circuit "get_author" is "closed", failures: 0
2023-06-05 21:53:20 WARNING:root:
2023-06-05 21:53:21 WARNING:root:Circuit "get_author" is "closed", failures: 0
2023-06-05 21:53:21 WARNING:root:
2023-06-05 21:53:22 WARNING:root:Circuit "get_author" is "closed", failures: 0
2023-06-05 21:53:22 WARNING:root:
2023-06-05 21:53:23 WARNING:root:Circuit "get_author" is "closed", failures: 0
2023-06-05 21:53:23 WARNING:root:
2023-06-05 21:53:24 WARNING:root:Circuit "get_author" is "closed", failures: 0
2023-06-05 21:53:24 WARNING:root:
2023-06-05 21:53:25 WARNING:root:Circuit "get_author" is "closed", failures: 0
2023-06-05 21:53:25 WARNING:root:
2023-06-05 21:53:26 WARNING:root:Circuit "get_author" is "closed", failures: 0
2023-06-05 21:53:27 WARNING:root:
2023-06-05 21:53:28 WARNING:root:Circuit "get_author" is "closed", failures: 0
2023-06-05 21:53:28 WARNING:root:
2023-06-05 21:53:29 WARNING:root:Circuit "get_author" is "closed", failures: 0
2023-06-05 21:53:29 WARNING:root:
2023-06-05 21:53:30 WARNING:root:Circuit "get_author" is "closed", failures: 0
2023-06-05 21:53:30 WARNING:root:
2023-06-05 21:53:31 WARNING:root:Circuit "get_author" is "closed", failures: 0
2023-06-05 21:53:31 WARNING:root:
2023-06-05 21:53:32 WARNING:root:Circuit "get_author" is "closed", failures: 0
2023-06-05 21:53:32 WARNING:root:
2023-06-05 21:53:33 WARNING:root:Circuit "get_author" is "closed", failures: 0
2023-06-05 21:53:33 WARNING:root:
2023-06-05 21:53:34 WARNING:root:Circuit "get_author" is "closed", failures: 0
2023-06-05 21:53:34 WARNING:root:
2023-06-05 21:53:35 WARNING:root:Circuit "get_author" is "closed", failures: 0
2023-06-05 21:53:35 WARNING:root:
2023-06-05 21:53:36 WARNING:root:Circuit "get_author" is "closed", failures: 0
2023-06-05 21:53:36 WARNING:root:
2023-06-05 21:53:37 WARNING:root:Circuit "get_author" is "closed", failures: 0
2023-06-05 21:53:37 WARNING:root:
2023-06-05 21:53:38 WARNING:root:Circuit "get_author" is "closed", failures: 0
2023-06-05 21:53:38 WARNING:root:
2023-06-05 21:53:39 WARNING:root:Circuit "get_author" is "closed", failures: 0
2023-06-05 21:53:39 WARNING:root:
2023-06-05 21:53:40 WARNING:root:Circuit "get_author" is "closed", failures: 0
2023-06-05 21:53:41 WARNING:root:
2023-06-05 21:53:42 WARNING:root:Circuit "get_author" is "closed", failures: 0
2023-06-05 21:53:42 WARNING:root:
2023-06-05 21:53:43 WARNING:root:Circuit "get_author" is "closed", failures: 0
2023-06-05 21:53:43 WARNING:root:
2023-06-05 21:53:44 WARNING:root:Circuit "get_author" is "closed", failures: 0
2023-06-05 21:53:44 WARNING:root:
2023-06-05 21:53:45 WARNING:root:Circuit "get_author" is "closed", failures: 0
2023-06-05 21:53:45 WARNING:root:
2023-06-05 21:53:46 WARNING:root:Circuit "get_author" is "closed", failures: 0
2023-06-05 21:53:46 WARNING:root:
2023-06-05 21:53:47 WARNING:root:Circuit "get_author" is "closed", failures: 0
2023-06-05 21:53:47 WARNING:root:
2023-06-05 21:53:48 WARNING:root:Circuit "get_author" is "closed", failures: 0
2023-06-05 21:53:48 WARNING:root:
2023-06-05 21:53:49 WARNING:root:Circuit "get_author" is "closed", failures: 0
2023-06-05 21:53:49 WARNING:root:
2023-06-05 21:53:50 WARNING:root:Circuit "get_author" is "closed", failures: 0
2023-06-05 21:53:50 WARNING:root:
2023-06-05 21:53:51 WARNING:root:Circuit "get_author" is "closed", failures: 0
2023-06-05 21:53:51 WARNING:root:
2023-06-05 21:53:52 WARNING:root:Circuit "get_author" is "closed", failures: 0
2023-06-05 21:53:52 WARNING:root:
2023-06-05 21:53:53 WARNING:root:Circuit "get_author" is "closed", failures: 0
2023-06-05 21:53:53 WARNING:root:
2023-06-05 21:53:54 WARNING:root:Circuit "get_author" is "closed", failures: 0
2023-06-05 21:53:54 WARNING:root:
2023-06-05 21:53:55 WARNING:root:Circuit "get_author" is "closed", failures: 0
2023-06-05 21:53:56 WARNING:root:
2023-06-05 21:53:56 Moore
2023-06-05 21:53:56 INFO:     172.18.0.1:43048 - "GET /presentationsAndAuthor/First%20Presentation HTTP/1.1" 200 OK
2023-06-05 21:53:57 WARNING:root:Circuit "get_author" is "closed", failures: 0
2023-06-05 21:53:57 WARNING:root:
2023-06-05 21:53:58 WARNING:root:Circuit "get_author" is "closed", failures: 0
2023-06-05 21:53:58 WARNING:root:
2023-06-05 21:53:59 WARNING:root:Circuit "get_author" is "closed", failures: 0
2023-06-05 21:53:59 WARNING:root:
2023-06-05 21:54:00 WARNING:root:Circuit "get_author" is "closed", failures: 0
2023-06-05 21:54:00 WARNING:root:
2023-06-05 21:54:01 WARNING:root:Circuit "get_author" is "closed", failures: 0
2023-06-05 21:54:01 WARNING:root:
2023-06-05 21:54:02 WARNING:root:Circuit "get_author" is "closed", failures: 0
2023-06-05 21:54:02 WARNING:root:
2023-06-05 21:54:03 WARNING:root:Circuit "get_author" is "closed", failures: 0
2023-06-05 21:54:03 WARNING:root:
2023-06-05 21:54:04 WARNING:root:Circuit "get_author" is "closed", failures: 0
2023-06-05 21:54:04 WARNING:root:
2023-06-05 21:54:05 WARNING:root:Circuit "get_author" is "closed", failures: 0
2023-06-05 21:54:05 WARNING:root:
2023-06-05 21:54:06 WARNING:root:Circuit "get_author" is "closed", failures: 0
2023-06-05 21:54:06 WARNING:root:
2023-06-05 21:54:07 WARNING:root:Circuit "get_author" is "closed", failures: 0
2023-06-05 21:54:07 WARNING:root:
2023-06-05 21:54:08 WARNING:root:Circuit "get_author" is "closed", failures: 0
2023-06-05 21:54:08 WARNING:root:
2023-06-05 21:54:09 WARNING:root:Circuit "get_author" is "closed", failures: 0
2023-06-05 21:54:09 WARNING:root:
2023-06-05 21:54:10 WARNING:root:Circuit "get_author" is "closed", failures: 0
2023-06-05 21:54:11 WARNING:root:
2023-06-05 21:54:12 WARNING:root:Circuit "get_author" is "closed", failures: 0
2023-06-05 21:54:12 WARNING:root:
2023-06-05 21:54:13 WARNING:root:Circuit "get_author" is "closed", failures: 0
2023-06-05 21:54:13 WARNING:root:
2023-06-05 21:54:14 WARNING:root:Circuit "get_author" is "closed", failures: 0
2023-06-05 21:54:14 WARNING:root:
2023-06-05 21:54:15 WARNING:root:Circuit "get_author" is "closed", failures: 0
2023-06-05 21:54:15 WARNING:root:
2023-06-05 21:54:16 WARNING:root:Circuit "get_author" is "closed", failures: 0
2023-06-05 21:54:16 WARNING:root:
2023-06-05 21:54:17 WARNING:root:Circuit "get_author" is "closed", failures: 0
2023-06-05 21:54:17 WARNING:root:
2023-06-05 21:54:12 Moore
2023-06-05 21:54:12 INFO:     172.18.0.1:43054 - "GET /presentationsAndAuthor/First%20Presentation HTTP/1.1" 200 OK
2023-06-05 21:54:18 WARNING:root:Circuit "get_author" is "closed", failures: 0
2023-06-05 21:54:18 WARNING:root:
2023-06-05 21:54:19 WARNING:root:Circuit "get_author" is "closed", failures: 0
2023-06-05 21:54:19 WARNING:root:
2023-06-05 21:54:20 WARNING:root:Circuit "get_author" is "closed", failures: 0
2023-06-05 21:54:20 WARNING:root:
2023-06-05 21:54:21 WARNING:root:Circuit "get_author" is "closed", failures: 0
2023-06-05 21:54:21 WARNING:root:
2023-06-05 21:54:22 WARNING:root:Circuit "get_author" is "closed", failures: 0
2023-06-05 21:54:22 WARNING:root:
2023-06-05 21:54:23 WARNING:root:Circuit "get_author" is "closed", failures: 0
2023-06-05 21:54:23 WARNING:root:
2023-06-05 21:54:24 WARNING:root:Circuit "get_author" is "closed", failures: 0
2023-06-05 21:54:24 WARNING:root:
2023-06-05 21:54:25 WARNING:root:Circuit "get_author" is "closed", failures: 0
2023-06-05 21:54:26 WARNING:root:
2023-06-05 21:54:27 WARNING:root:Circuit "get_author" is "closed", failures: 0
2023-06-05 21:54:27 WARNING:root:
2023-06-05 21:54:28 WARNING:root:Circuit "get_author" is "closed", failures: 0
2023-06-05 21:54:28 WARNING:root:
2023-06-05 21:54:29 WARNING:root:Circuit "get_author" is "closed", failures: 0
2023-06-05 21:54:29 WARNING:root:
2023-06-05 21:54:30 WARNING:root:Circuit "get_author" is "closed", failures: 0
2023-06-05 21:54:30 WARNING:root:
2023-06-05 21:54:31 WARNING:root:Circuit "get_author" is "closed", failures: 0
2023-06-05 21:54:31 WARNING:root:
2023-06-05 21:54:32 WARNING:root:Circuit "get_author" is "closed", failures: 0
2023-06-05 21:54:32 WARNING:root:
2023-06-05 21:54:33 WARNING:root:Circuit "get_author" is "closed", failures: 0
2023-06-05 21:54:33 WARNING:root:
2023-06-05 21:54:35 WARNING:root:Circuit "get_author" is "closed", failures: 0
2023-06-05 21:54:35 WARNING:root:
2023-06-05 21:54:36 WARNING:root:Circuit "get_author" is "closed", failures: 0
2023-06-05 21:54:36 WARNING:root:
2023-06-05 21:54:37 WARNING:root:Circuit "get_author" is "closed", failures: 0
2023-06-05 21:54:37 WARNING:root:
2023-06-05 21:54:38 WARNING:root:Circuit "get_author" is "closed", failures: 0
2023-06-05 21:54:38 WARNING:root:
2023-06-05 21:54:39 WARNING:root:Circuit "get_author" is "closed", failures: 0
2023-06-05 21:54:39 WARNING:root:
2023-06-05 21:54:41 WARNING:root:Circuit "get_author" is "closed", failures: 0
2023-06-05 21:54:41 WARNING:root:
2023-06-05 21:54:42 WARNING:root:Circuit "get_author" is "closed", failures: 0
2023-06-05 21:54:42 WARNING:root:
2023-06-05 21:54:43 WARNING:root:Circuit "get_author" is "closed", failures: 0
2023-06-05 21:54:43 WARNING:root:
2023-06-05 21:54:44 WARNING:root:Circuit "get_author" is "closed", failures: 0
2023-06-05 21:54:44 WARNING:root:
2023-06-05 21:54:45 WARNING:root:Circuit "get_author" is "closed", failures: 0
2023-06-05 21:54:45 WARNING:root:
2023-06-05 21:54:46 WARNING:root:Circuit "get_author" is "closed", failures: 0
2023-06-05 21:54:46 WARNING:root:
2023-06-05 21:54:47 WARNING:root:Circuit "get_author" is "closed", failures: 0
2023-06-05 21:54:47 WARNING:root:
2023-06-05 21:54:48 WARNING:root:Circuit "get_author" is "closed", failures: 0
2023-06-05 21:54:48 WARNING:root:
2023-06-05 21:54:49 WARNING:root:Circuit "get_author" is "closed", failures: 0
2023-06-05 21:54:49 WARNING:root:
2023-06-05 21:54:50 WARNING:root:Circuit "get_author" is "closed", failures: 0
2023-06-05 21:54:50 WARNING:root:
2023-06-05 21:54:51 WARNING:root:Circuit "get_author" is "closed", failures: 0
2023-06-05 21:54:51 WARNING:root:
2023-06-05 21:54:52 WARNING:root:Circuit "get_author" is "closed", failures: 0
2023-06-05 21:54:52 WARNING:root:
2023-06-05 21:54:53 WARNING:root:Circuit "get_author" is "closed", failures: 0
2023-06-05 21:54:53 WARNING:root:
2023-06-05 21:54:54 WARNING:root:Circuit "get_author" is "closed", failures: 0
2023-06-05 21:54:54 WARNING:root:
2023-06-05 21:54:55 WARNING:root:Circuit "get_author" is "closed", failures: 0
2023-06-05 21:54:56 WARNING:root:
2023-06-05 21:54:57 WARNING:root:Circuit "get_author" is "closed", failures: 0
2023-06-05 21:54:57 WARNING:root:
2023-06-05 21:54:58 WARNING:root:Circuit "get_author" is "closed", failures: 0
2023-06-05 21:54:58 WARNING:root:
2023-06-05 21:54:59 WARNING:root:Circuit "get_author" is "closed", failures: 0
2023-06-05 21:54:59 WARNING:root:
2023-06-05 21:55:00 WARNING:root:Circuit "get_author" is "closed", failures: 0
2023-06-05 21:55:00 WARNING:root:
2023-06-05 21:55:01 WARNING:root:Circuit "get_author" is "closed", failures: 0
2023-06-05 21:55:01 WARNING:root:
2023-06-05 21:55:02 WARNING:root:Circuit "get_author" is "closed", failures: 0
2023-06-05 21:55:02 WARNING:root:
2023-06-05 21:55:03 WARNING:root:Circuit "get_author" is "closed", failures: 0
2023-06-05 21:55:03 WARNING:root:
2023-06-05 21:55:04 WARNING:root:Circuit "get_author" is "closed", failures: 0
2023-06-05 21:55:04 WARNING:root:
2023-06-05 21:55:05 WARNING:root:Circuit "get_author" is "closed", failures: 0
2023-06-05 21:55:05 WARNING:root:
2023-06-05 21:55:06 WARNING:root:Circuit "get_author" is "closed", failures: 0
2023-06-05 21:55:06 WARNING:root:
2023-06-05 21:55:07 WARNING:root:Circuit "get_author" is "closed", failures: 0
2023-06-05 21:55:07 WARNING:root:
2023-06-05 21:55:08 WARNING:root:Circuit "get_author" is "closed", failures: 0
2023-06-05 21:55:08 WARNING:root:
2023-06-05 21:55:09 WARNING:root:Circuit "get_author" is "closed", failures: 0
2023-06-05 21:55:09 WARNING:root:
2023-06-05 21:55:10 WARNING:root:Circuit "get_author" is "closed", failures: 0
2023-06-05 21:55:10 WARNING:root:
2023-06-05 21:55:11 WARNING:root:Circuit "get_author" is "closed", failures: 0
2023-06-05 21:55:11 WARNING:root:
2023-06-05 21:55:12 WARNING:root:Circuit "get_author" is "closed", failures: 0
2023-06-05 21:55:12 WARNING:root:
2023-06-05 21:55:13 WARNING:root:Circuit "get_author" is "closed", failures: 0
2023-06-05 21:55:14 WARNING:root:
2023-06-05 21:55:15 WARNING:root:Circuit "get_author" is "closed", failures: 0
2023-06-05 21:55:15 WARNING:root:
2023-06-05 21:55:16 WARNING:root:Circuit "get_author" is "closed", failures: 0
2023-06-05 21:55:16 WARNING:root:
2023-06-05 21:55:17 WARNING:root:Circuit "get_author" is "closed", failures: 0
2023-06-05 21:55:17 WARNING:root:
2023-06-05 21:55:18 WARNING:root:Circuit "get_author" is "closed", failures: 0
2023-06-05 21:55:18 WARNING:root:
2023-06-05 21:55:19 WARNING:root:Circuit "get_author" is "closed", failures: 0
2023-06-05 21:55:19 WARNING:root:
2023-06-05 21:55:20 WARNING:root:Circuit "get_author" is "closed", failures: 0
2023-06-05 21:55:20 WARNING:root:
2023-06-05 21:55:21 WARNING:root:Circuit "get_author" is "closed", failures: 0
2023-06-05 21:55:21 WARNING:root:
2023-06-05 21:55:22 WARNING:root:Circuit "get_author" is "closed", failures: 0
2023-06-05 21:55:22 WARNING:root:
2023-06-05 21:55:23 WARNING:root:Circuit "get_author" is "closed", failures: 0
2023-06-05 21:55:23 WARNING:root:
2023-06-05 21:55:24 WARNING:root:Circuit "get_author" is "closed", failures: 0
2023-06-05 21:55:24 WARNING:root:
2023-06-05 21:55:25 WARNING:root:Circuit "get_author" is "closed", failures: 0
2023-06-05 21:55:26 WARNING:root:
2023-06-05 21:55:27 WARNING:root:Circuit "get_author" is "closed", failures: 0
2023-06-05 21:55:27 WARNING:root:
2023-06-05 21:55:28 WARNING:root:Circuit "get_author" is "closed", failures: 0
2023-06-05 21:55:28 WARNING:root:
2023-06-05 21:55:29 WARNING:root:Circuit "get_author" is "closed", failures: 0
2023-06-05 21:55:29 WARNING:root:
2023-06-05 21:55:30 WARNING:root:Circuit "get_author" is "closed", failures: 0
2023-06-05 21:55:30 WARNING:root:
2023-06-05 21:55:31 WARNING:root:Circuit "get_author" is "closed", failures: 0
2023-06-05 21:55:31 WARNING:root:
2023-06-05 21:55:32 WARNING:root:Circuit "get_author" is "closed", failures: 0
2023-06-05 21:55:32 WARNING:root:
2023-06-05 21:55:33 WARNING:root:Circuit "get_author" is "closed", failures: 0
2023-06-05 21:55:33 WARNING:root:
2023-06-05 21:55:34 WARNING:root:Circuit "get_author" is "closed", failures: 0
2023-06-05 21:55:34 WARNING:root:
2023-06-05 21:55:35 WARNING:root:Circuit "get_author" is "closed", failures: 0
2023-06-05 21:55:35 WARNING:root:
2023-06-05 21:55:36 WARNING:root:Circuit "get_author" is "closed", failures: 0
2023-06-05 21:55:36 WARNING:root:
2023-06-05 21:55:37 WARNING:root:Circuit "get_author" is "closed", failures: 0
2023-06-05 21:55:37 WARNING:root:
2023-06-05 21:55:38 WARNING:root:Circuit "get_author" is "closed", failures: 0
2023-06-05 21:55:38 WARNING:root:
2023-06-05 21:55:39 WARNING:root:Circuit "get_author" is "closed", failures: 0
2023-06-05 21:55:39 WARNING:root:
2023-06-05 21:55:40 WARNING:root:Circuit "get_author" is "closed", failures: 0
2023-06-05 21:55:40 WARNING:root:
2023-06-05 21:55:41 WARNING:root:Circuit "get_author" is "closed", failures: 0
2023-06-05 21:55:41 WARNING:root:
2023-06-05 21:55:42 WARNING:root:Circuit "get_author" is "closed", failures: 0
2023-06-05 21:55:42 WARNING:root:
2023-06-05 21:55:43 WARNING:root:Circuit "get_author" is "closed", failures: 0
2023-06-05 21:55:43 WARNING:root:
2023-06-05 21:55:44 WARNING:root:Circuit "get_author" is "closed", failures: 0
2023-06-05 21:55:44 WARNING:root:
2023-06-05 21:55:45 WARNING:root:Circuit "get_author" is "closed", failures: 0
2023-06-05 21:55:45 WARNING:root:
2023-06-05 21:55:46 WARNING:root:Circuit "get_author" is "closed", failures: 0
2023-06-05 21:55:46 WARNING:root:
2023-06-05 21:55:47 WARNING:root:Circuit "get_author" is "closed", failures: 0
2023-06-05 21:55:47 WARNING:root:
2023-06-05 21:55:48 WARNING:root:Circuit "get_author" is "closed", failures: 0
2023-06-05 21:55:48 WARNING:root:
2023-06-05 21:55:49 WARNING:root:Circuit "get_author" is "closed", failures: 0
2023-06-05 21:55:49 WARNING:root:
2023-06-05 21:55:50 WARNING:root:Circuit "get_author" is "closed", failures: 0
2023-06-05 21:55:50 WARNING:root:
2023-06-05 21:55:51 WARNING:root:Circuit "get_author" is "closed", failures: 0
2023-06-05 21:55:51 WARNING:root:
2023-06-05 21:55:52 WARNING:root:Circuit "get_author" is "closed", failures: 0
2023-06-05 21:55:52 WARNING:root:
2023-06-05 21:55:54 WARNING:root:Circuit "get_author" is "closed", failures: 0
2023-06-05 21:55:54 WARNING:root:
2023-06-05 21:55:55 WARNING:root:Circuit "get_author" is "closed", failures: 0
2023-06-05 21:55:55 WARNING:root:
2023-06-05 21:55:56 WARNING:root:Circuit "get_author" is "closed", failures: 0
2023-06-05 21:55:56 WARNING:root:
2023-06-05 21:55:57 WARNING:root:Circuit "get_author" is "closed", failures: 0
2023-06-05 21:55:57 WARNING:root:
2023-06-05 21:55:58 WARNING:root:Circuit "get_author" is "closed", failures: 0
2023-06-05 21:55:58 WARNING:root:
2023-06-05 21:55:58 --- Logging error ---
2023-06-05 21:55:59 Traceback (most recent call last):
2023-06-05 21:55:59   File "/usr/local/lib/python3.10/dist-packages/urllib3/connection.py", line 174, in _new_conn
2023-06-05 21:55:59     conn = connection.create_connection(
2023-06-05 21:55:59   File "/usr/local/lib/python3.10/dist-packages/urllib3/util/connection.py", line 72, in create_connection
2023-06-05 21:55:59     for res in socket.getaddrinfo(host, port, family, socket.SOCK_STREAM):
2023-06-05 21:55:59   File "/usr/lib/python3.10/socket.py", line 955, in getaddrinfo
2023-06-05 21:55:59     for res in _socket.getaddrinfo(host, port, family, type, proto, flags):
2023-06-05 21:55:59 socket.gaierror: [Errno -3] Temporary failure in name resolution
2023-06-05 21:55:59 
2023-06-05 21:55:59 During handling of the above exception, another exception occurred:
2023-06-05 21:55:59 
2023-06-05 21:55:59 Traceback (most recent call last):
2023-06-05 21:55:59   File "/usr/local/lib/python3.10/dist-packages/urllib3/connectionpool.py", line 703, in urlopen
2023-06-05 21:55:59     httplib_response = self._make_request(
2023-06-05 21:55:59   File "/usr/local/lib/python3.10/dist-packages/urllib3/connectionpool.py", line 398, in _make_request
2023-06-05 21:55:59     conn.request(method, url, **httplib_request_kw)
2023-06-05 21:55:59   File "/usr/local/lib/python3.10/dist-packages/urllib3/connection.py", line 239, in request
2023-06-05 21:55:59     super(HTTPConnection, self).request(method, url, body=body, headers=headers)
2023-06-05 21:55:59   File "/usr/lib/python3.10/http/client.py", line 1282, in request
2023-06-05 21:55:59     self._send_request(method, url, body, headers, encode_chunked)
2023-06-05 21:55:59   File "/usr/lib/python3.10/http/client.py", line 1328, in _send_request
2023-06-05 21:55:59     self.endheaders(body, encode_chunked=encode_chunked)
2023-06-05 21:55:59   File "/usr/lib/python3.10/http/client.py", line 1277, in endheaders
2023-06-05 21:55:59     self._send_output(message_body, encode_chunked=encode_chunked)
2023-06-05 21:55:59   File "/usr/lib/python3.10/http/client.py", line 1037, in _send_output
2023-06-05 21:55:59     self.send(msg)
2023-06-05 21:55:59   File "/usr/lib/python3.10/http/client.py", line 975, in send
2023-06-05 21:55:59     self.connect()
2023-06-05 21:55:59   File "/usr/local/lib/python3.10/dist-packages/urllib3/connection.py", line 205, in connect
2023-06-05 21:55:59     conn = self._new_conn()
2023-06-05 21:55:59   File "/usr/local/lib/python3.10/dist-packages/urllib3/connection.py", line 186, in _new_conn
2023-06-05 21:55:59     raise NewConnectionError(
2023-06-05 21:55:59 urllib3.exceptions.NewConnectionError: <urllib3.connection.HTTPConnection object at 0x7fd9be627100>: Failed to establish a new connection: [Errno -3] Temporary failure in name resolution
2023-06-05 21:55:59 
2023-06-05 21:55:59 During handling of the above exception, another exception occurred:
2023-06-05 21:55:59 
2023-06-05 21:55:59 Traceback (most recent call last):
2023-06-05 21:55:59   File "/usr/local/lib/python3.10/dist-packages/requests/adapters.py", line 489, in send
2023-06-05 21:55:59     resp = conn.urlopen(
2023-06-05 21:55:59   File "/usr/local/lib/python3.10/dist-packages/urllib3/connectionpool.py", line 787, in urlopen
2023-06-05 21:55:59     retries = retries.increment(
2023-06-05 21:55:59   File "/usr/local/lib/python3.10/dist-packages/urllib3/util/retry.py", line 592, in increment
2023-06-05 21:55:59     raise MaxRetryError(_pool, url, error or ResponseError(cause))
2023-06-05 21:55:59 urllib3.exceptions.MaxRetryError: HTTPConnectionPool(host='service_author', port=8081): Max retries exceeded with url: /authors/1 (Caused by NewConnectionError('<urllib3.connection.HTTPConnection object at 0x7fd9be627100>: Failed to establish a new connection: [Errno -3] Temporary failure in name resolution'))
2023-06-05 21:55:59 
2023-06-05 21:55:59 During handling of the above exception, another exception occurred:
2023-06-05 21:55:59 
2023-06-05 21:55:59 Traceback (most recent call last):
2023-06-05 21:55:59   File "/./service_main.py", line 74, in get_author
2023-06-05 21:55:59     response_author = requests.get("http://" + service_author + "/authors/" + str(id))
2023-06-05 21:55:59   File "/usr/local/lib/python3.10/dist-packages/requests/api.py", line 73, in get
2023-06-05 21:55:59     return request("get", url, params=params, **kwargs)
2023-06-05 21:55:59   File "/usr/local/lib/python3.10/dist-packages/requests/api.py", line 59, in request
2023-06-05 21:55:59     return session.request(method=method, url=url, **kwargs)
2023-06-05 21:55:59   File "/usr/local/lib/python3.10/dist-packages/requests/sessions.py", line 587, in request
2023-06-05 21:55:59     resp = self.send(prep, **send_kwargs)
2023-06-05 21:55:59   File "/usr/local/lib/python3.10/dist-packages/requests/sessions.py", line 701, in send
2023-06-05 21:55:59     r = adapter.send(request, **kwargs)
2023-06-05 21:55:59   File "/usr/local/lib/python3.10/dist-packages/requests/adapters.py", line 565, in send
2023-06-05 21:55:59     raise ConnectionError(e, request=request)
2023-06-05 21:55:59 requests.exceptions.ConnectionError: HTTPConnectionPool(host='service_author', port=8081): Max retries exceeded with url: /authors/1 (Caused by NewConnectionError('<urllib3.connection.HTTPConnection object at 0x7fd9be627100>: Failed to establish a new connection: [Errno -3] Temporary failure in name resolution'))
2023-06-05 21:55:59 
2023-06-05 21:55:59 During handling of the above exception, another exception occurred:
2023-06-05 21:55:59 
2023-06-05 21:55:59 Traceback (most recent call last):
2023-06-05 21:55:59   File "/usr/lib/python3.10/logging/__init__.py", line 1100, in emit
2023-06-05 21:55:59     msg = self.format(record)
2023-06-05 21:55:59   File "/usr/lib/python3.10/logging/__init__.py", line 943, in format
2023-06-05 21:55:59     return fmt.format(record)
2023-06-05 21:55:59   File "/usr/lib/python3.10/logging/__init__.py", line 678, in format
2023-06-05 21:55:59     record.message = record.getMessage()
2023-06-05 21:55:59   File "/usr/lib/python3.10/logging/__init__.py", line 368, in getMessage
2023-06-05 21:55:59     msg = msg % self.args
2023-06-05 21:55:59 TypeError: not all arguments converted during string formatting
2023-06-05 21:55:59 Call stack:
2023-06-05 21:56:01 INFO:     172.18.0.1:43062 - "GET /presentationsAndAuthor/First%20Presentation HTTP/1.1" 500 Internal Server Error
2023-06-05 21:56:01   File "<string>", line 1, in <module>
2023-06-05 21:56:01   File "/usr/lib/python3.10/multiprocessing/spawn.py", line 116, in spawn_main
2023-06-05 21:56:01     exitcode = _main(fd, parent_sentinel)
2023-06-05 21:56:01   File "/usr/lib/python3.10/multiprocessing/spawn.py", line 129, in _main
2023-06-05 21:56:01     return self._bootstrap(parent_sentinel)
2023-06-05 21:56:01   File "/usr/lib/python3.10/multiprocessing/process.py", line 314, in _bootstrap
2023-06-05 21:56:01     self.run()
2023-06-05 21:56:01   File "/usr/lib/python3.10/multiprocessing/process.py", line 108, in run
2023-06-05 21:56:01     self._target(*self._args, **self._kwargs)
2023-06-05 21:56:01   File "/usr/local/lib/python3.10/dist-packages/uvicorn/_subprocess.py", line 76, in subprocess_started
2023-06-05 21:56:01     target(sockets=sockets)
2023-06-05 21:56:01   File "/usr/local/lib/python3.10/dist-packages/uvicorn/server.py", line 60, in run
2023-06-05 21:56:01     return asyncio.run(self.serve(sockets=sockets))
2023-06-05 21:56:01   File "/usr/lib/python3.10/asyncio/runners.py", line 44, in run
2023-06-05 21:56:01     return loop.run_until_complete(main)
2023-06-05 21:56:01   File "/usr/lib/python3.10/asyncio/base_events.py", line 633, in run_until_complete
2023-06-05 21:56:01     self.run_forever()
2023-06-05 21:56:01   File "/usr/lib/python3.10/asyncio/base_events.py", line 600, in run_forever
2023-06-05 21:56:01     self._run_once()
2023-06-05 21:56:01   File "/usr/lib/python3.10/asyncio/base_events.py", line 1896, in _run_once
2023-06-05 21:56:01     handle._run()
2023-06-05 21:56:01   File "/usr/lib/python3.10/asyncio/events.py", line 80, in _run
2023-06-05 21:56:01     self._context.run(self._callback, *self._args)
2023-06-05 21:56:01   File "/usr/local/lib/python3.10/dist-packages/uvicorn/protocols/http/httptools_impl.py", line 419, in run_asgi
2023-06-05 21:56:01     result = await app(  # type: ignore[func-returns-value]
2023-06-05 21:56:01   File "/usr/local/lib/python3.10/dist-packages/uvicorn/middleware/proxy_headers.py", line 78, in __call__
2023-06-05 21:56:01     return await self.app(scope, receive, send)
2023-06-05 21:56:01   File "/usr/local/lib/python3.10/dist-packages/fastapi/applications.py", line 271, in __call__
2023-06-05 21:56:01     await super().__call__(scope, receive, send)
2023-06-05 21:56:01   File "/usr/local/lib/python3.10/dist-packages/starlette/applications.py", line 118, in __call__
2023-06-05 21:56:01     await self.middleware_stack(scope, receive, send)
2023-06-05 21:56:01   File "/usr/local/lib/python3.10/dist-packages/starlette/middleware/errors.py", line 162, in __call__
2023-06-05 21:56:01     await self.app(scope, receive, _send)
2023-06-05 21:56:01   File "/usr/local/lib/python3.10/dist-packages/starlette/middleware/exceptions.py", line 68, in __call__
2023-06-05 21:56:01     await self.app(scope, receive, sender)
2023-06-05 21:56:01   File "/usr/local/lib/python3.10/dist-packages/fastapi/middleware/asyncexitstack.py", line 18, in __call__
2023-06-05 21:56:01     await self.app(scope, receive, send)
2023-06-05 21:56:01   File "/usr/local/lib/python3.10/dist-packages/starlette/routing.py", line 706, in __call__
2023-06-05 21:56:01     await route.handle(scope, receive, send)
2023-06-05 21:56:01   File "/usr/local/lib/python3.10/dist-packages/starlette/routing.py", line 276, in handle
2023-06-05 21:56:01     await self.app(scope, receive, send)
2023-06-05 21:56:01   File "/usr/local/lib/python3.10/dist-packages/starlette/routing.py", line 66, in app
2023-06-05 21:56:01     response = await func(request)
2023-06-05 21:56:01   File "/usr/local/lib/python3.10/dist-packages/fastapi/routing.py", line 237, in app
2023-06-05 21:56:01     raw_response = await run_endpoint_function(
2023-06-05 21:56:01   File "/usr/local/lib/python3.10/dist-packages/fastapi/routing.py", line 163, in run_endpoint_function
2023-06-05 21:56:01     return await dependant.call(**values)
2023-06-05 21:56:01   File "/./service_main.py", line 105, in read_presentation
2023-06-05 21:56:01     author = get_author(presentation.author_id)
2023-06-05 21:56:01   File "/./circuitbreaker.py", line 159, in wrapper
2023-06-05 21:56:01     return call(function, *args, **kwargs)
2023-06-05 21:56:01   File "/./circuitbreaker.py", line 170, in call
2023-06-05 21:56:01     return func(*args, **kwargs)
2023-06-05 21:56:01   File "/./service_main.py", line 76, in get_author
2023-06-05 21:56:01     logging.warning(">>> Error Connecting:", errc)
2023-06-05 21:56:01 Message: '>>> Error Connecting:'
2023-06-05 21:56:01 Arguments: (ConnectionError(MaxRetryError("HTTPConnectionPool(host='service_author', port=8081): Max retries exceeded with url: /authors/1 (Caused by NewConnectionError('<urllib3.connection.HTTPConnection object at 0x7fd9be627100>: Failed to establish a new connection: [Errno -3] Temporary failure in name resolution'))")),)
2023-06-05 21:56:01 WARNING:root:Circuit "get_author" is "closed", failures: 0
2023-06-05 21:56:01 WARNING:root:
2023-06-05 21:56:02 WARNING:root:Circuit "get_author" is "closed", failures: 1
2023-06-05 21:56:02 WARNING:root:
2023-06-05 21:56:03 WARNING:root:Circuit "get_author" is "closed", failures: 1
2023-06-05 21:56:03 WARNING:root:
2023-06-05 21:56:04 WARNING:root:Circuit "get_author" is "closed", failures: 1
2023-06-05 21:56:04 WARNING:root:
2023-06-05 21:56:05 WARNING:root:Circuit "get_author" is "closed", failures: 1
2023-06-05 21:56:05 WARNING:root:
2023-06-05 21:56:06 WARNING:root:Circuit "get_author" is "closed", failures: 1
2023-06-05 21:56:06 WARNING:root:
2023-06-05 21:56:07 WARNING:root:Circuit "get_author" is "closed", failures: 1
2023-06-05 21:56:07 WARNING:root:
2023-06-05 21:56:08 WARNING:root:Circuit "get_author" is "closed", failures: 1
2023-06-05 21:56:08 WARNING:root:
2023-06-05 21:56:09 WARNING:root:Circuit "get_author" is "closed", failures: 1
2023-06-05 21:56:09 WARNING:root:
2023-06-05 21:56:10 WARNING:root:Circuit "get_author" is "closed", failures: 1
2023-06-05 21:56:10 WARNING:root:
2023-06-05 21:56:11 WARNING:root:Circuit "get_author" is "closed", failures: 1
2023-06-05 21:56:11 WARNING:root:
2023-06-05 21:56:12 WARNING:root:Circuit "get_author" is "closed", failures: 1
2023-06-05 21:56:12 WARNING:root:
2023-06-05 21:56:13 WARNING:root:Circuit "get_author" is "closed", failures: 1
2023-06-05 21:56:13 WARNING:root:
2023-06-05 21:56:14 WARNING:root:Circuit "get_author" is "closed", failures: 1
2023-06-05 21:56:14 WARNING:root:
2023-06-05 21:56:15 WARNING:root:Circuit "get_author" is "closed", failures: 1
2023-06-05 21:56:16 WARNING:root:
2023-06-05 21:56:17 WARNING:root:Circuit "get_author" is "closed", failures: 1
2023-06-05 21:56:17 WARNING:root:
2023-06-05 21:56:18 WARNING:root:Circuit "get_author" is "closed", failures: 1
2023-06-05 21:56:18 WARNING:root:
2023-06-05 21:56:19 WARNING:root:Circuit "get_author" is "closed", failures: 1
2023-06-05 21:56:19 WARNING:root:
2023-06-05 21:56:20 WARNING:root:Circuit "get_author" is "closed", failures: 1
2023-06-05 21:56:20 WARNING:root:
2023-06-05 21:56:21 --- Logging error ---
2023-06-05 21:56:21 Traceback (most recent call last):
2023-06-05 21:56:21   File "/usr/local/lib/python3.10/dist-packages/urllib3/connection.py", line 174, in _new_conn
2023-06-05 21:56:21     conn = connection.create_connection(
2023-06-05 21:56:21   File "/usr/local/lib/python3.10/dist-packages/urllib3/util/connection.py", line 72, in create_connection
2023-06-05 21:56:21     for res in socket.getaddrinfo(host, port, family, socket.SOCK_STREAM):
2023-06-05 21:56:21   File "/usr/lib/python3.10/socket.py", line 955, in getaddrinfo
2023-06-05 21:56:21     for res in _socket.getaddrinfo(host, port, family, type, proto, flags):
2023-06-05 21:56:21 socket.gaierror: [Errno -3] Temporary failure in name resolution
2023-06-05 21:56:21 
2023-06-05 21:56:21 During handling of the above exception, another exception occurred:
2023-06-05 21:56:21 
2023-06-05 21:56:21 Traceback (most recent call last):
2023-06-05 21:56:21   File "/usr/local/lib/python3.10/dist-packages/urllib3/connectionpool.py", line 703, in urlopen
2023-06-05 21:56:21     httplib_response = self._make_request(
2023-06-05 21:56:21   File "/usr/local/lib/python3.10/dist-packages/urllib3/connectionpool.py", line 398, in _make_request
2023-06-05 21:56:21     conn.request(method, url, **httplib_request_kw)
2023-06-05 21:56:21   File "/usr/local/lib/python3.10/dist-packages/urllib3/connection.py", line 239, in request
2023-06-05 21:56:21     super(HTTPConnection, self).request(method, url, body=body, headers=headers)
2023-06-05 21:56:21   File "/usr/lib/python3.10/http/client.py", line 1282, in request
2023-06-05 21:56:21     self._send_request(method, url, body, headers, encode_chunked)
2023-06-05 21:56:21   File "/usr/lib/python3.10/http/client.py", line 1328, in _send_request
2023-06-05 21:56:21     self.endheaders(body, encode_chunked=encode_chunked)
2023-06-05 21:56:21   File "/usr/lib/python3.10/http/client.py", line 1277, in endheaders
2023-06-05 21:56:21     self._send_output(message_body, encode_chunked=encode_chunked)
2023-06-05 21:56:21   File "/usr/lib/python3.10/http/client.py", line 1037, in _send_output
2023-06-05 21:56:21     self.send(msg)
2023-06-05 21:56:21   File "/usr/lib/python3.10/http/client.py", line 975, in send
2023-06-05 21:56:21     self.connect()
2023-06-05 21:56:21   File "/usr/local/lib/python3.10/dist-packages/urllib3/connection.py", line 205, in connect
2023-06-05 21:56:21     conn = self._new_conn()
2023-06-05 21:56:21   File "/usr/local/lib/python3.10/dist-packages/urllib3/connection.py", line 186, in _new_conn
2023-06-05 21:56:21     raise NewConnectionError(
2023-06-05 21:56:21 urllib3.exceptions.NewConnectionError: <urllib3.connection.HTTPConnection object at 0x7fd9bdbe8940>: Failed to establish a new connection: [Errno -3] Temporary failure in name resolution
2023-06-05 21:56:21 
2023-06-05 21:56:21 During handling of the above exception, another exception occurred:
2023-06-05 21:56:21 
2023-06-05 21:56:21 Traceback (most recent call last):
2023-06-05 21:56:21   File "/usr/local/lib/python3.10/dist-packages/requests/adapters.py", line 489, in send
2023-06-05 21:56:21     resp = conn.urlopen(
2023-06-05 21:56:21   File "/usr/local/lib/python3.10/dist-packages/urllib3/connectionpool.py", line 787, in urlopen
2023-06-05 21:56:21     retries = retries.increment(
2023-06-05 21:56:21   File "/usr/local/lib/python3.10/dist-packages/urllib3/util/retry.py", line 592, in increment
2023-06-05 21:56:21     raise MaxRetryError(_pool, url, error or ResponseError(cause))
2023-06-05 21:56:21 urllib3.exceptions.MaxRetryError: HTTPConnectionPool(host='service_author', port=8081): Max retries exceeded with url: /authors/1 (Caused by NewConnectionError('<urllib3.connection.HTTPConnection object at 0x7fd9bdbe8940>: Failed to establish a new connection: [Errno -3] Temporary failure in name resolution'))
2023-06-05 21:56:21 
2023-06-05 21:56:21 During handling of the above exception, another exception occurred:
2023-06-05 21:56:21 
2023-06-05 21:56:21 Traceback (most recent call last):
2023-06-05 21:56:21   File "/./service_main.py", line 74, in get_author
2023-06-05 21:56:21     response_author = requests.get("http://" + service_author + "/authors/" + str(id))
2023-06-05 21:56:21   File "/usr/local/lib/python3.10/dist-packages/requests/api.py", line 73, in get
2023-06-05 21:56:21     return request("get", url, params=params, **kwargs)
2023-06-05 21:56:21   File "/usr/local/lib/python3.10/dist-packages/requests/api.py", line 59, in request
2023-06-05 21:56:21     return session.request(method=method, url=url, **kwargs)
2023-06-05 21:56:21   File "/usr/local/lib/python3.10/dist-packages/requests/sessions.py", line 587, in request
2023-06-05 21:56:21     resp = self.send(prep, **send_kwargs)
2023-06-05 21:56:21   File "/usr/local/lib/python3.10/dist-packages/requests/sessions.py", line 701, in send
2023-06-05 21:56:21     r = adapter.send(request, **kwargs)
2023-06-05 21:56:21   File "/usr/local/lib/python3.10/dist-packages/requests/adapters.py", line 565, in send
2023-06-05 21:56:21     raise ConnectionError(e, request=request)
2023-06-05 21:56:21 requests.exceptions.ConnectionError: HTTPConnectionPool(host='service_author', port=8081): Max retries exceeded with url: /authors/1 (Caused by NewConnectionError('<urllib3.connection.HTTPConnection object at 0x7fd9bdbe8940>: Failed to establish a new connection: [Errno -3] Temporary failure in name resolution'))
2023-06-05 21:56:21 
2023-06-05 21:56:21 During handling of the above exception, another exception occurred:
2023-06-05 21:56:21 
2023-06-05 21:56:21 Traceback (most recent call last):
2023-06-05 21:56:21   File "/usr/lib/python3.10/logging/__init__.py", line 1100, in emit
2023-06-05 21:56:21     msg = self.format(record)
2023-06-05 21:56:21   File "/usr/lib/python3.10/logging/__init__.py", line 943, in format
2023-06-05 21:56:21     return fmt.format(record)
2023-06-05 21:56:21   File "/usr/lib/python3.10/logging/__init__.py", line 678, in format
2023-06-05 21:56:21     record.message = record.getMessage()
2023-06-05 21:56:21   File "/usr/lib/python3.10/logging/__init__.py", line 368, in getMessage
2023-06-05 21:56:21     msg = msg % self.args
2023-06-05 21:56:21 TypeError: not all arguments converted during string formatting
2023-06-05 21:56:21 Call stack:
2023-06-05 21:56:21   File "<string>", line 1, in <module>
2023-06-05 21:56:21   File "/usr/lib/python3.10/multiprocessing/spawn.py", line 116, in spawn_main
2023-06-05 21:56:21     exitcode = _main(fd, parent_sentinel)
2023-06-05 21:56:21   File "/usr/lib/python3.10/multiprocessing/spawn.py", line 129, in _main
2023-06-05 21:56:21     return self._bootstrap(parent_sentinel)
2023-06-05 21:56:21   File "/usr/lib/python3.10/multiprocessing/process.py", line 314, in _bootstrap
2023-06-05 21:56:21     self.run()
2023-06-05 21:56:21   File "/usr/lib/python3.10/multiprocessing/process.py", line 108, in run
2023-06-05 21:56:21     self._target(*self._args, **self._kwargs)
2023-06-05 21:56:21   File "/usr/local/lib/python3.10/dist-packages/uvicorn/_subprocess.py", line 76, in subprocess_started
2023-06-05 21:56:21     target(sockets=sockets)
2023-06-05 21:56:21   File "/usr/local/lib/python3.10/dist-packages/uvicorn/server.py", line 60, in run
2023-06-05 21:56:21     return asyncio.run(self.serve(sockets=sockets))
2023-06-05 21:56:21   File "/usr/lib/python3.10/asyncio/runners.py", line 44, in run
2023-06-05 21:56:21     return loop.run_until_complete(main)
2023-06-05 21:56:21   File "/usr/lib/python3.10/asyncio/base_events.py", line 633, in run_until_complete
2023-06-05 21:56:21     self.run_forever()
2023-06-05 21:56:21   File "/usr/lib/python3.10/asyncio/base_events.py", line 600, in run_forever
2023-06-05 21:56:21     self._run_once()
2023-06-05 21:56:21   File "/usr/lib/python3.10/asyncio/base_events.py", line 1896, in _run_once
2023-06-05 21:56:21     handle._run()
2023-06-05 21:56:21   File "/usr/lib/python3.10/asyncio/events.py", line 80, in _run
2023-06-05 21:56:21     self._context.run(self._callback, *self._args)
2023-06-05 21:56:21   File "/usr/local/lib/python3.10/dist-packages/uvicorn/protocols/http/httptools_impl.py", line 419, in run_asgi
2023-06-05 21:56:21     result = await app(  # type: ignore[func-returns-value]
2023-06-05 21:56:21   File "/usr/local/lib/python3.10/dist-packages/uvicorn/middleware/proxy_headers.py", line 78, in __call__
2023-06-05 21:56:21     return await self.app(scope, receive, send)
2023-06-05 21:56:21   File "/usr/local/lib/python3.10/dist-packages/fastapi/applications.py", line 271, in __call__
2023-06-05 21:56:21     await super().__call__(scope, receive, send)
2023-06-05 21:56:21   File "/usr/local/lib/python3.10/dist-packages/starlette/applications.py", line 118, in __call__
2023-06-05 21:56:21     await self.middleware_stack(scope, receive, send)
2023-06-05 21:56:21   File "/usr/local/lib/python3.10/dist-packages/starlette/middleware/errors.py", line 162, in __call__
2023-06-05 21:56:21     await self.app(scope, receive, _send)
2023-06-05 21:56:21   File "/usr/local/lib/python3.10/dist-packages/starlette/middleware/exceptions.py", line 68, in __call__
2023-06-05 21:56:21     await self.app(scope, receive, sender)
2023-06-05 21:56:21   File "/usr/local/lib/python3.10/dist-packages/fastapi/middleware/asyncexitstack.py", line 18, in __call__
2023-06-05 21:56:21     await self.app(scope, receive, send)
2023-06-05 21:56:21   File "/usr/local/lib/python3.10/dist-packages/starlette/routing.py", line 706, in __call__
2023-06-05 21:56:21     await route.handle(scope, receive, send)
2023-06-05 21:56:21   File "/usr/local/lib/python3.10/dist-packages/starlette/routing.py", line 276, in handle
2023-06-05 21:56:21     await self.app(scope, receive, send)
2023-06-05 21:56:21   File "/usr/local/lib/python3.10/dist-packages/starlette/routing.py", line 66, in app
2023-06-05 21:56:21     response = await func(request)
2023-06-05 21:56:21   File "/usr/local/lib/python3.10/dist-packages/fastapi/routing.py", line 237, in app
2023-06-05 21:56:21     raw_response = await run_endpoint_function(
2023-06-05 21:56:21   File "/usr/local/lib/python3.10/dist-packages/fastapi/routing.py", line 163, in run_endpoint_function
2023-06-05 21:56:21     return await dependant.call(**values)
2023-06-05 21:56:21   File "/./service_main.py", line 105, in read_presentation
2023-06-05 21:56:21     author = get_author(presentation.author_id)
2023-06-05 21:56:21   File "/./circuitbreaker.py", line 159, in wrapper
2023-06-05 21:56:21     return call(function, *args, **kwargs)
2023-06-05 21:56:21   File "/./circuitbreaker.py", line 170, in call
2023-06-05 21:56:21     return func(*args, **kwargs)
2023-06-05 21:56:21   File "/./service_main.py", line 76, in get_author
2023-06-05 21:56:21     logging.warning(">>> Error Connecting:", errc)
2023-06-05 21:56:21 Message: '>>> Error Connecting:'
2023-06-05 21:56:21 Arguments: (ConnectionError(MaxRetryError("HTTPConnectionPool(host='service_author', port=8081): Max retries exceeded with url: /authors/1 (Caused by NewConnectionError('<urllib3.connection.HTTPConnection object at 0x7fd9bdbe8940>: Failed to establish a new connection: [Errno -3] Temporary failure in name resolution'))")),)
2023-06-05 21:56:21 INFO:     172.18.0.1:43066 - "GET /presentationsAndAuthor/First%20Presentation HTTP/1.1" 500 Internal Server Error
2023-06-05 21:56:21 WARNING:root:Circuit "get_author" is "closed", failures: 2
2023-06-05 21:56:21 WARNING:root:
2023-06-05 21:56:22 WARNING:root:Circuit "get_author" is "closed", failures: 2
2023-06-05 21:56:22 WARNING:root:
2023-06-05 21:56:23 WARNING:root:Circuit "get_author" is "closed", failures: 2
2023-06-05 21:56:23 WARNING:root:
2023-06-05 21:56:24 WARNING:root:Circuit "get_author" is "closed", failures: 2
2023-06-05 21:56:24 WARNING:root:
2023-06-05 21:56:25 WARNING:root:Circuit "get_author" is "closed", failures: 2
2023-06-05 21:56:25 WARNING:root:
2023-06-05 21:56:26 WARNING:root:Circuit "get_author" is "closed", failures: 2
2023-06-05 21:56:26 WARNING:root:
2023-06-05 21:56:27 WARNING:root:Circuit "get_author" is "closed", failures: 2
2023-06-05 21:56:27 WARNING:root:
2023-06-05 21:56:28 WARNING:root:Circuit "get_author" is "closed", failures: 2
2023-06-05 21:56:28 WARNING:root:
2023-06-05 21:56:29 WARNING:root:Circuit "get_author" is "closed", failures: 2
2023-06-05 21:56:29 WARNING:root:
2023-06-05 21:56:30 WARNING:root:Circuit "get_author" is "closed", failures: 2
2023-06-05 21:56:30 WARNING:root:
2023-06-05 21:56:31 WARNING:root:Circuit "get_author" is "closed", failures: 2
2023-06-05 21:56:32 WARNING:root:
2023-06-05 21:56:33 WARNING:root:Circuit "get_author" is "closed", failures: 2
2023-06-05 21:56:33 WARNING:root:
2023-06-05 21:56:34 WARNING:root:Circuit "get_author" is "closed", failures: 2
2023-06-05 21:56:34 WARNING:root:
2023-06-05 21:56:35 WARNING:root:Circuit "get_author" is "closed", failures: 2
2023-06-05 21:56:35 WARNING:root:
2023-06-05 21:56:36 WARNING:root:Circuit "get_author" is "closed", failures: 2
2023-06-05 21:56:36 WARNING:root:
2023-06-05 21:56:37 --- Logging error ---
2023-06-05 21:56:37 Traceback (most recent call last):
2023-06-05 21:56:37   File "/usr/local/lib/python3.10/dist-packages/urllib3/connection.py", line 174, in _new_conn
2023-06-05 21:56:37     conn = connection.create_connection(
2023-06-05 21:56:37   File "/usr/local/lib/python3.10/dist-packages/urllib3/util/connection.py", line 72, in create_connection
2023-06-05 21:56:37     for res in socket.getaddrinfo(host, port, family, socket.SOCK_STREAM):
2023-06-05 21:56:37   File "/usr/lib/python3.10/socket.py", line 955, in getaddrinfo
2023-06-05 21:56:37     for res in _socket.getaddrinfo(host, port, family, type, proto, flags):
2023-06-05 21:56:37 socket.gaierror: [Errno -3] Temporary failure in name resolution
2023-06-05 21:56:37 
2023-06-05 21:56:37 During handling of the above exception, another exception occurred:
2023-06-05 21:56:37 
2023-06-05 21:56:37 Traceback (most recent call last):
2023-06-05 21:56:37   File "/usr/local/lib/python3.10/dist-packages/urllib3/connectionpool.py", line 703, in urlopen
2023-06-05 21:56:37     httplib_response = self._make_request(
2023-06-05 21:56:37   File "/usr/local/lib/python3.10/dist-packages/urllib3/connectionpool.py", line 398, in _make_request
2023-06-05 21:56:37     conn.request(method, url, **httplib_request_kw)
2023-06-05 21:56:37   File "/usr/local/lib/python3.10/dist-packages/urllib3/connection.py", line 239, in request
2023-06-05 21:56:37     super(HTTPConnection, self).request(method, url, body=body, headers=headers)
2023-06-05 21:56:37   File "/usr/lib/python3.10/http/client.py", line 1282, in request
2023-06-05 21:56:37     self._send_request(method, url, body, headers, encode_chunked)
2023-06-05 21:56:37   File "/usr/lib/python3.10/http/client.py", line 1328, in _send_request
2023-06-05 21:56:37     self.endheaders(body, encode_chunked=encode_chunked)
2023-06-05 21:56:37   File "/usr/lib/python3.10/http/client.py", line 1277, in endheaders
2023-06-05 21:56:37     self._send_output(message_body, encode_chunked=encode_chunked)
2023-06-05 21:56:37   File "/usr/lib/python3.10/http/client.py", line 1037, in _send_output
2023-06-05 21:56:37     self.send(msg)
2023-06-05 21:56:37   File "/usr/lib/python3.10/http/client.py", line 975, in send
2023-06-05 21:56:37     self.connect()
2023-06-05 21:56:37   File "/usr/local/lib/python3.10/dist-packages/urllib3/connection.py", line 205, in connect
2023-06-05 21:56:37     conn = self._new_conn()
2023-06-05 21:56:37   File "/usr/local/lib/python3.10/dist-packages/urllib3/connection.py", line 186, in _new_conn
2023-06-05 21:56:37     raise NewConnectionError(
2023-06-05 21:56:37 urllib3.exceptions.NewConnectionError: <urllib3.connection.HTTPConnection object at 0x7fd9bdbe9720>: Failed to establish a new connection: [Errno -3] Temporary failure in name resolution
2023-06-05 21:56:37 
2023-06-05 21:56:37 During handling of the above exception, another exception occurred:
2023-06-05 21:56:37 
2023-06-05 21:56:37 Traceback (most recent call last):
2023-06-05 21:56:37   File "/usr/local/lib/python3.10/dist-packages/requests/adapters.py", line 489, in send
2023-06-05 21:56:37     resp = conn.urlopen(
2023-06-05 21:56:37   File "/usr/local/lib/python3.10/dist-packages/urllib3/connectionpool.py", line 787, in urlopen
2023-06-05 21:56:37     retries = retries.increment(
2023-06-05 21:56:37   File "/usr/local/lib/python3.10/dist-packages/urllib3/util/retry.py", line 592, in increment
2023-06-05 21:56:37     raise MaxRetryError(_pool, url, error or ResponseError(cause))
2023-06-05 21:56:37 urllib3.exceptions.MaxRetryError: HTTPConnectionPool(host='service_author', port=8081): Max retries exceeded with url: /authors/1 (Caused by NewConnectionError('<urllib3.connection.HTTPConnection object at 0x7fd9bdbe9720>: Failed to establish a new connection: [Errno -3] Temporary failure in name resolution'))
2023-06-05 21:56:37 
2023-06-05 21:56:37 During handling of the above exception, another exception occurred:
2023-06-05 21:56:37 
2023-06-05 21:56:37 Traceback (most recent call last):
2023-06-05 21:56:37   File "/./service_main.py", line 74, in get_author
2023-06-05 21:56:37     response_author = requests.get("http://" + service_author + "/authors/" + str(id))
2023-06-05 21:56:37   File "/usr/local/lib/python3.10/dist-packages/requests/api.py", line 73, in get
2023-06-05 21:56:37     return request("get", url, params=params, **kwargs)
2023-06-05 21:56:37   File "/usr/local/lib/python3.10/dist-packages/requests/api.py", line 59, in request
2023-06-05 21:56:37     return session.request(method=method, url=url, **kwargs)
2023-06-05 21:56:37   File "/usr/local/lib/python3.10/dist-packages/requests/sessions.py", line 587, in request
2023-06-05 21:56:37     resp = self.send(prep, **send_kwargs)
2023-06-05 21:56:37   File "/usr/local/lib/python3.10/dist-packages/requests/sessions.py", line 701, in send
2023-06-05 21:56:37     r = adapter.send(request, **kwargs)
2023-06-05 21:56:37   File "/usr/local/lib/python3.10/dist-packages/requests/adapters.py", line 565, in send
2023-06-05 21:56:37     raise ConnectionError(e, request=request)
2023-06-05 21:56:37 requests.exceptions.ConnectionError: HTTPConnectionPool(host='service_author', port=8081): Max retries exceeded with url: /authors/1 (Caused by NewConnectionError('<urllib3.connection.HTTPConnection object at 0x7fd9bdbe9720>: Failed to establish a new connection: [Errno -3] Temporary failure in name resolution'))
2023-06-05 21:56:37 
2023-06-05 21:56:37 During handling of the above exception, another exception occurred:
2023-06-05 21:56:37 
2023-06-05 21:56:37 Traceback (most recent call last):
2023-06-05 21:56:37   File "/usr/lib/python3.10/logging/__init__.py", line 1100, in emit
2023-06-05 21:56:37     msg = self.format(record)
2023-06-05 21:56:37   File "/usr/lib/python3.10/logging/__init__.py", line 943, in format
2023-06-05 21:56:37     return fmt.format(record)
2023-06-05 21:56:37   File "/usr/lib/python3.10/logging/__init__.py", line 678, in format
2023-06-05 21:56:37     record.message = record.getMessage()
2023-06-05 21:56:37   File "/usr/lib/python3.10/logging/__init__.py", line 368, in getMessage
2023-06-05 21:56:37     msg = msg % self.args
2023-06-05 21:56:37 TypeError: not all arguments converted during string formatting
2023-06-05 21:56:37 Call stack:
2023-06-05 21:56:37   File "<string>", line 1, in <module>
2023-06-05 21:56:37   File "/usr/lib/python3.10/multiprocessing/spawn.py", line 116, in spawn_main
2023-06-05 21:56:37     exitcode = _main(fd, parent_sentinel)
2023-06-05 21:56:37   File "/usr/lib/python3.10/multiprocessing/spawn.py", line 129, in _main
2023-06-05 21:56:37     return self._bootstrap(parent_sentinel)
2023-06-05 21:56:37   File "/usr/lib/python3.10/multiprocessing/process.py", line 314, in _bootstrap
2023-06-05 21:56:37     self.run()
2023-06-05 21:56:37   File "/usr/lib/python3.10/multiprocessing/process.py", line 108, in run
2023-06-05 21:56:37     self._target(*self._args, **self._kwargs)
2023-06-05 21:56:37   File "/usr/local/lib/python3.10/dist-packages/uvicorn/_subprocess.py", line 76, in subprocess_started
2023-06-05 21:56:37     target(sockets=sockets)
2023-06-05 21:56:37   File "/usr/local/lib/python3.10/dist-packages/uvicorn/server.py", line 60, in run
2023-06-05 21:56:37     return asyncio.run(self.serve(sockets=sockets))
2023-06-05 21:56:37   File "/usr/lib/python3.10/asyncio/runners.py", line 44, in run
2023-06-05 21:56:37     return loop.run_until_complete(main)
2023-06-05 21:56:37   File "/usr/lib/python3.10/asyncio/base_events.py", line 633, in run_until_complete
2023-06-05 21:56:37     self.run_forever()
2023-06-05 21:56:37   File "/usr/lib/python3.10/asyncio/base_events.py", line 600, in run_forever
2023-06-05 21:56:37     self._run_once()
2023-06-05 21:56:37   File "/usr/lib/python3.10/asyncio/base_events.py", line 1896, in _run_once
2023-06-05 21:56:37     handle._run()
2023-06-05 21:56:37   File "/usr/lib/python3.10/asyncio/events.py", line 80, in _run
2023-06-05 21:56:37     self._context.run(self._callback, *self._args)
2023-06-05 21:56:37   File "/usr/local/lib/python3.10/dist-packages/uvicorn/protocols/http/httptools_impl.py", line 419, in run_asgi
2023-06-05 21:56:37     result = await app(  # type: ignore[func-returns-value]
2023-06-05 21:56:37   File "/usr/local/lib/python3.10/dist-packages/uvicorn/middleware/proxy_headers.py", line 78, in __call__
2023-06-05 21:56:37     return await self.app(scope, receive, send)
2023-06-05 21:56:37   File "/usr/local/lib/python3.10/dist-packages/fastapi/applications.py", line 271, in __call__
2023-06-05 21:56:37     await super().__call__(scope, receive, send)
2023-06-05 21:56:37   File "/usr/local/lib/python3.10/dist-packages/starlette/applications.py", line 118, in __call__
2023-06-05 21:56:37     await self.middleware_stack(scope, receive, send)
2023-06-05 21:56:37   File "/usr/local/lib/python3.10/dist-packages/starlette/middleware/errors.py", line 162, in __call__
2023-06-05 21:56:37     await self.app(scope, receive, _send)
2023-06-05 21:56:37   File "/usr/local/lib/python3.10/dist-packages/starlette/middleware/exceptions.py", line 68, in __call__
2023-06-05 21:56:37     await self.app(scope, receive, sender)
2023-06-05 21:56:37   File "/usr/local/lib/python3.10/dist-packages/fastapi/middleware/asyncexitstack.py", line 18, in __call__
2023-06-05 21:56:37     await self.app(scope, receive, send)
2023-06-05 21:56:37   File "/usr/local/lib/python3.10/dist-packages/starlette/routing.py", line 706, in __call__
2023-06-05 21:56:37     await route.handle(scope, receive, send)
2023-06-05 21:56:37   File "/usr/local/lib/python3.10/dist-packages/starlette/routing.py", line 276, in handle
2023-06-05 21:56:37     await self.app(scope, receive, send)
2023-06-05 21:56:37   File "/usr/local/lib/python3.10/dist-packages/starlette/routing.py", line 66, in app
2023-06-05 21:56:37     response = await func(request)
2023-06-05 21:56:37   File "/usr/local/lib/python3.10/dist-packages/fastapi/routing.py", line 237, in app
2023-06-05 21:56:37     raw_response = await run_endpoint_function(
2023-06-05 21:56:37   File "/usr/local/lib/python3.10/dist-packages/fastapi/routing.py", line 163, in run_endpoint_function
2023-06-05 21:56:37     return await dependant.call(**values)
2023-06-05 21:56:37   File "/./service_main.py", line 105, in read_presentation
2023-06-05 21:56:37     author = get_author(presentation.author_id)
2023-06-05 21:56:37   File "/./circuitbreaker.py", line 159, in wrapper
2023-06-05 21:56:37     return call(function, *args, **kwargs)
2023-06-05 21:56:37   File "/./circuitbreaker.py", line 170, in call
2023-06-05 21:56:37     return func(*args, **kwargs)
2023-06-05 21:56:37   File "/./service_main.py", line 76, in get_author
2023-06-05 21:56:37     logging.warning(">>> Error Connecting:", errc)
2023-06-05 21:56:37 Message: '>>> Error Connecting:'
2023-06-05 21:56:37 Arguments: (ConnectionError(MaxRetryError("HTTPConnectionPool(host='service_author', port=8081): Max retries exceeded with url: /authors/1 (Caused by NewConnectionError('<urllib3.connection.HTTPConnection object at 0x7fd9bdbe9720>: Failed to establish a new connection: [Errno -3] Temporary failure in name resolution'))")),)
2023-06-05 21:56:37 INFO:     172.18.0.1:43070 - "GET /presentationsAndAuthor/First%20Presentation HTTP/1.1" 500 Internal Server Error
2023-06-05 21:56:37 WARNING:root:Circuit "get_author" is "closed", failures: 3
2023-06-05 21:56:37 WARNING:root:
2023-06-05 21:56:38 WARNING:root:Circuit "get_author" is "closed", failures: 3
2023-06-05 21:56:38 WARNING:root:
2023-06-05 21:56:39 WARNING:root:Circuit "get_author" is "closed", failures: 3
2023-06-05 21:56:39 WARNING:root:
2023-06-05 21:56:40 WARNING:root:Circuit "get_author" is "closed", failures: 3
2023-06-05 21:56:40 WARNING:root:
2023-06-05 21:56:41 WARNING:root:Circuit "get_author" is "closed", failures: 3
2023-06-05 21:56:41 WARNING:root:
2023-06-05 21:56:42 WARNING:root:Circuit "get_author" is "closed", failures: 3
2023-06-05 21:56:42 WARNING:root:
2023-06-05 21:56:43 WARNING:root:Circuit "get_author" is "closed", failures: 3
2023-06-05 21:56:43 WARNING:root:
2023-06-05 21:56:44 WARNING:root:Circuit "get_author" is "closed", failures: 3
2023-06-05 21:56:44 WARNING:root:
2023-06-05 21:56:45 WARNING:root:Circuit "get_author" is "closed", failures: 3
2023-06-05 21:56:45 WARNING:root:
2023-06-05 21:56:46 WARNING:root:Circuit "get_author" is "closed", failures: 3
2023-06-05 21:56:46 WARNING:root:
2023-06-05 21:56:48 WARNING:root:Circuit "get_author" is "closed", failures: 3
2023-06-05 21:56:48 WARNING:root:
2023-06-05 21:56:49 WARNING:root:Circuit "get_author" is "closed", failures: 3
2023-06-05 21:56:49 WARNING:root:
2023-06-05 21:56:50 WARNING:root:Circuit "get_author" is "closed", failures: 3
2023-06-05 21:56:50 WARNING:root:
2023-06-05 21:56:51 WARNING:root:Circuit "get_author" is "closed", failures: 3
2023-06-05 21:56:51 WARNING:root:
2023-06-05 21:56:52 WARNING:root:Circuit "get_author" is "closed", failures: 3
2023-06-05 21:56:52 WARNING:root:
2023-06-05 21:56:52 --- Logging error ---
2023-06-05 21:56:52 Traceback (most recent call last):
2023-06-05 21:56:52   File "/usr/local/lib/python3.10/dist-packages/urllib3/connection.py", line 174, in _new_conn
2023-06-05 21:56:52     conn = connection.create_connection(
2023-06-05 21:56:52   File "/usr/local/lib/python3.10/dist-packages/urllib3/util/connection.py", line 72, in create_connection
2023-06-05 21:56:52     for res in socket.getaddrinfo(host, port, family, socket.SOCK_STREAM):
2023-06-05 21:56:52   File "/usr/lib/python3.10/socket.py", line 955, in getaddrinfo
2023-06-05 21:56:52     for res in _socket.getaddrinfo(host, port, family, type, proto, flags):
2023-06-05 21:56:52 socket.gaierror: [Errno -3] Temporary failure in name resolution
2023-06-05 21:56:52 
2023-06-05 21:56:52 During handling of the above exception, another exception occurred:
2023-06-05 21:56:52 
2023-06-05 21:56:52 Traceback (most recent call last):
2023-06-05 21:56:52   File "/usr/local/lib/python3.10/dist-packages/urllib3/connectionpool.py", line 703, in urlopen
2023-06-05 21:56:52     httplib_response = self._make_request(
2023-06-05 21:56:52   File "/usr/local/lib/python3.10/dist-packages/urllib3/connectionpool.py", line 398, in _make_request
2023-06-05 21:56:52     conn.request(method, url, **httplib_request_kw)
2023-06-05 21:56:52   File "/usr/local/lib/python3.10/dist-packages/urllib3/connection.py", line 239, in request
2023-06-05 21:56:52     super(HTTPConnection, self).request(method, url, body=body, headers=headers)
2023-06-05 21:56:52   File "/usr/lib/python3.10/http/client.py", line 1282, in request
2023-06-05 21:56:52     self._send_request(method, url, body, headers, encode_chunked)
2023-06-05 21:56:52   File "/usr/lib/python3.10/http/client.py", line 1328, in _send_request
2023-06-05 21:56:52     self.endheaders(body, encode_chunked=encode_chunked)
2023-06-05 21:56:52   File "/usr/lib/python3.10/http/client.py", line 1277, in endheaders
2023-06-05 21:56:52     self._send_output(message_body, encode_chunked=encode_chunked)
2023-06-05 21:56:52   File "/usr/lib/python3.10/http/client.py", line 1037, in _send_output
2023-06-05 21:56:52     self.send(msg)
2023-06-05 21:56:52   File "/usr/lib/python3.10/http/client.py", line 975, in send
2023-06-05 21:56:52     self.connect()
2023-06-05 21:56:52   File "/usr/local/lib/python3.10/dist-packages/urllib3/connection.py", line 205, in connect
2023-06-05 21:56:52     conn = self._new_conn()
2023-06-05 21:56:52   File "/usr/local/lib/python3.10/dist-packages/urllib3/connection.py", line 186, in _new_conn
2023-06-05 21:56:52     raise NewConnectionError(
2023-06-05 21:56:52 urllib3.exceptions.NewConnectionError: <urllib3.connection.HTTPConnection object at 0x7fd9bdbea5f0>: Failed to establish a new connection: [Errno -3] Temporary failure in name resolution
2023-06-05 21:56:52 
2023-06-05 21:56:52 During handling of the above exception, another exception occurred:
2023-06-05 21:56:52 
2023-06-05 21:56:52 Traceback (most recent call last):
2023-06-05 21:56:52   File "/usr/local/lib/python3.10/dist-packages/requests/adapters.py", line 489, in send
2023-06-05 21:56:52     resp = conn.urlopen(
2023-06-05 21:56:52   File "/usr/local/lib/python3.10/dist-packages/urllib3/connectionpool.py", line 787, in urlopen
2023-06-05 21:56:52     retries = retries.increment(
2023-06-05 21:56:52   File "/usr/local/lib/python3.10/dist-packages/urllib3/util/retry.py", line 592, in increment
2023-06-05 21:56:52     raise MaxRetryError(_pool, url, error or ResponseError(cause))
2023-06-05 21:56:52 urllib3.exceptions.MaxRetryError: HTTPConnectionPool(host='service_author', port=8081): Max retries exceeded with url: /authors/1 (Caused by NewConnectionError('<urllib3.connection.HTTPConnection object at 0x7fd9bdbea5f0>: Failed to establish a new connection: [Errno -3] Temporary failure in name resolution'))
2023-06-05 21:56:52 
2023-06-05 21:56:52 During handling of the above exception, another exception occurred:
2023-06-05 21:56:52 
2023-06-05 21:56:52 Traceback (most recent call last):
2023-06-05 21:56:52   File "/./service_main.py", line 74, in get_author
2023-06-05 21:56:52     response_author = requests.get("http://" + service_author + "/authors/" + str(id))
2023-06-05 21:56:52   File "/usr/local/lib/python3.10/dist-packages/requests/api.py", line 73, in get
2023-06-05 21:56:52     return request("get", url, params=params, **kwargs)
2023-06-05 21:56:52   File "/usr/local/lib/python3.10/dist-packages/requests/api.py", line 59, in request
2023-06-05 21:56:52     return session.request(method=method, url=url, **kwargs)
2023-06-05 21:56:52   File "/usr/local/lib/python3.10/dist-packages/requests/sessions.py", line 587, in request
2023-06-05 21:56:52     resp = self.send(prep, **send_kwargs)
2023-06-05 21:56:52   File "/usr/local/lib/python3.10/dist-packages/requests/sessions.py", line 701, in send
2023-06-05 21:56:52     r = adapter.send(request, **kwargs)
2023-06-05 21:56:52   File "/usr/local/lib/python3.10/dist-packages/requests/adapters.py", line 565, in send
2023-06-05 21:56:52     raise ConnectionError(e, request=request)
2023-06-05 21:56:52 requests.exceptions.ConnectionError: HTTPConnectionPool(host='service_author', port=8081): Max retries exceeded with url: /authors/1 (Caused by NewConnectionError('<urllib3.connection.HTTPConnection object at 0x7fd9bdbea5f0>: Failed to establish a new connection: [Errno -3] Temporary failure in name resolution'))
2023-06-05 21:56:52 
2023-06-05 21:56:52 During handling of the above exception, another exception occurred:
2023-06-05 21:56:52 
2023-06-05 21:56:52 Traceback (most recent call last):
2023-06-05 21:56:52   File "/usr/lib/python3.10/logging/__init__.py", line 1100, in emit
2023-06-05 21:56:52     msg = self.format(record)
2023-06-05 21:56:52   File "/usr/lib/python3.10/logging/__init__.py", line 943, in format
2023-06-05 21:56:52     return fmt.format(record)
2023-06-05 21:56:52   File "/usr/lib/python3.10/logging/__init__.py", line 678, in format
2023-06-05 21:56:52     record.message = record.getMessage()
2023-06-05 21:56:52   File "/usr/lib/python3.10/logging/__init__.py", line 368, in getMessage
2023-06-05 21:56:52     msg = msg % self.args
2023-06-05 21:56:52 TypeError: not all arguments converted during string formatting
2023-06-05 21:56:52 Call stack:
2023-06-05 21:56:52   File "<string>", line 1, in <module>
2023-06-05 21:56:52   File "/usr/lib/python3.10/multiprocessing/spawn.py", line 116, in spawn_main
2023-06-05 21:56:52     exitcode = _main(fd, parent_sentinel)
2023-06-05 21:56:52   File "/usr/lib/python3.10/multiprocessing/spawn.py", line 129, in _main
2023-06-05 21:56:52     return self._bootstrap(parent_sentinel)
2023-06-05 21:56:52   File "/usr/lib/python3.10/multiprocessing/process.py", line 314, in _bootstrap
2023-06-05 21:56:52     self.run()
2023-06-05 21:56:52   File "/usr/lib/python3.10/multiprocessing/process.py", line 108, in run
2023-06-05 21:56:52     self._target(*self._args, **self._kwargs)
2023-06-05 21:56:52   File "/usr/local/lib/python3.10/dist-packages/uvicorn/_subprocess.py", line 76, in subprocess_started
2023-06-05 21:56:52     target(sockets=sockets)
2023-06-05 21:56:52   File "/usr/local/lib/python3.10/dist-packages/uvicorn/server.py", line 60, in run
2023-06-05 21:56:52     return asyncio.run(self.serve(sockets=sockets))
2023-06-05 21:56:52   File "/usr/lib/python3.10/asyncio/runners.py", line 44, in run
2023-06-05 21:56:52     return loop.run_until_complete(main)
2023-06-05 21:56:52   File "/usr/lib/python3.10/asyncio/base_events.py", line 633, in run_until_complete
2023-06-05 21:56:52     self.run_forever()
2023-06-05 21:56:52   File "/usr/lib/python3.10/asyncio/base_events.py", line 600, in run_forever
2023-06-05 21:56:52     self._run_once()
2023-06-05 21:56:52   File "/usr/lib/python3.10/asyncio/base_events.py", line 1896, in _run_once
2023-06-05 21:56:52     handle._run()
2023-06-05 21:56:52   File "/usr/lib/python3.10/asyncio/events.py", line 80, in _run
2023-06-05 21:56:52     self._context.run(self._callback, *self._args)
2023-06-05 21:56:52   File "/usr/local/lib/python3.10/dist-packages/uvicorn/protocols/http/httptools_impl.py", line 419, in run_asgi
2023-06-05 21:56:52     result = await app(  # type: ignore[func-returns-value]
2023-06-05 21:56:52   File "/usr/local/lib/python3.10/dist-packages/uvicorn/middleware/proxy_headers.py", line 78, in __call__
2023-06-05 21:56:52     return await self.app(scope, receive, send)
2023-06-05 21:56:52   File "/usr/local/lib/python3.10/dist-packages/fastapi/applications.py", line 271, in __call__
2023-06-05 21:56:52     await super().__call__(scope, receive, send)
2023-06-05 21:56:52   File "/usr/local/lib/python3.10/dist-packages/starlette/applications.py", line 118, in __call__
2023-06-05 21:56:52     await self.middleware_stack(scope, receive, send)
2023-06-05 21:56:52   File "/usr/local/lib/python3.10/dist-packages/starlette/middleware/errors.py", line 162, in __call__
2023-06-05 21:56:52     await self.app(scope, receive, _send)
2023-06-05 21:56:52   File "/usr/local/lib/python3.10/dist-packages/starlette/middleware/exceptions.py", line 68, in __call__
2023-06-05 21:56:52     await self.app(scope, receive, sender)
2023-06-05 21:56:52   File "/usr/local/lib/python3.10/dist-packages/fastapi/middleware/asyncexitstack.py", line 18, in __call__
2023-06-05 21:56:52     await self.app(scope, receive, send)
2023-06-05 21:56:52   File "/usr/local/lib/python3.10/dist-packages/starlette/routing.py", line 706, in __call__
2023-06-05 21:56:52     await route.handle(scope, receive, send)
2023-06-05 21:56:52   File "/usr/local/lib/python3.10/dist-packages/starlette/routing.py", line 276, in handle
2023-06-05 21:56:52     await self.app(scope, receive, send)
2023-06-05 21:56:52   File "/usr/local/lib/python3.10/dist-packages/starlette/routing.py", line 66, in app
2023-06-05 21:56:52     response = await func(request)
2023-06-05 21:56:52   File "/usr/local/lib/python3.10/dist-packages/fastapi/routing.py", line 237, in app
2023-06-05 21:56:52     raw_response = await run_endpoint_function(
2023-06-05 21:56:52   File "/usr/local/lib/python3.10/dist-packages/fastapi/routing.py", line 163, in run_endpoint_function
2023-06-05 21:56:52     return await dependant.call(**values)
2023-06-05 21:56:52   File "/./service_main.py", line 105, in read_presentation
2023-06-05 21:56:52     author = get_author(presentation.author_id)
2023-06-05 21:56:52   File "/./circuitbreaker.py", line 159, in wrapper
2023-06-05 21:56:52     return call(function, *args, **kwargs)
2023-06-05 21:56:52   File "/./circuitbreaker.py", line 170, in call
2023-06-05 21:56:52     return func(*args, **kwargs)
2023-06-05 21:56:52   File "/./service_main.py", line 76, in get_author
2023-06-05 21:56:52     logging.warning(">>> Error Connecting:", errc)
2023-06-05 21:56:52 Message: '>>> Error Connecting:'
2023-06-05 21:56:52 Arguments: (ConnectionError(MaxRetryError("HTTPConnectionPool(host='service_author', port=8081): Max retries exceeded with url: /authors/1 (Caused by NewConnectionError('<urllib3.connection.HTTPConnection object at 0x7fd9bdbea5f0>: Failed to establish a new connection: [Errno -3] Temporary failure in name resolution'))")),)
2023-06-05 21:56:52 INFO:     172.18.0.1:43074 - "GET /presentationsAndAuthor/First%20Presentation HTTP/1.1" 500 Internal Server Error
2023-06-05 21:56:53 WARNING:root:Circuit "get_author" is "closed", failures: 4
2023-06-05 21:56:53 WARNING:root:
2023-06-05 21:56:54 WARNING:root:Circuit "get_author" is "closed", failures: 4
2023-06-05 21:56:54 WARNING:root:
2023-06-05 21:56:55 WARNING:root:Circuit "get_author" is "closed", failures: 4
2023-06-05 21:56:55 WARNING:root:
2023-06-05 21:56:56 WARNING:root:Circuit "get_author" is "closed", failures: 4
2023-06-05 21:56:56 WARNING:root:
2023-06-05 21:56:57 WARNING:root:Circuit "get_author" is "closed", failures: 4
2023-06-05 21:56:57 WARNING:root:
2023-06-05 21:56:58 WARNING:root:Circuit "get_author" is "closed", failures: 4
2023-06-05 21:56:58 WARNING:root:
2023-06-05 21:56:59 WARNING:root:Circuit "get_author" is "closed", failures: 4
2023-06-05 21:56:59 WARNING:root:
2023-06-05 21:57:00 WARNING:root:Circuit "get_author" is "closed", failures: 4
2023-06-05 21:57:00 WARNING:root:
2023-06-05 21:57:01 WARNING:root:Circuit "get_author" is "closed", failures: 4
2023-06-05 21:57:01 WARNING:root:
2023-06-05 21:57:03 WARNING:root:Circuit "get_author" is "closed", failures: 4
2023-06-05 21:57:04 WARNING:root:
2023-06-05 21:57:05 WARNING:root:Circuit "get_author" is "closed", failures: 4
2023-06-05 21:57:05 WARNING:root:
2023-06-05 21:57:06 WARNING:root:Circuit "get_author" is "closed", failures: 4
2023-06-05 21:57:06 WARNING:root:
2023-06-05 21:57:07 INFO:     172.18.0.1:43078 - "GET /presentationsAndAuthor/First%20Presentation HTTP/1.1" 500 Internal Server Error
2023-06-05 21:57:07 --- Logging error ---
2023-06-05 21:57:07 Traceback (most recent call last):
2023-06-05 21:57:07   File "/usr/local/lib/python3.10/dist-packages/urllib3/connection.py", line 174, in _new_conn
2023-06-05 21:57:07     conn = connection.create_connection(
2023-06-05 21:57:07   File "/usr/local/lib/python3.10/dist-packages/urllib3/util/connection.py", line 72, in create_connection
2023-06-05 21:57:07     for res in socket.getaddrinfo(host, port, family, socket.SOCK_STREAM):
2023-06-05 21:57:07   File "/usr/lib/python3.10/socket.py", line 955, in getaddrinfo
2023-06-05 21:57:07     for res in _socket.getaddrinfo(host, port, family, type, proto, flags):
2023-06-05 21:57:07 socket.gaierror: [Errno -3] Temporary failure in name resolution
2023-06-05 21:57:07 
2023-06-05 21:57:07 During handling of the above exception, another exception occurred:
2023-06-05 21:57:07 
2023-06-05 21:57:07 Traceback (most recent call last):
2023-06-05 21:57:07   File "/usr/local/lib/python3.10/dist-packages/urllib3/connectionpool.py", line 703, in urlopen
2023-06-05 21:57:07     httplib_response = self._make_request(
2023-06-05 21:57:07   File "/usr/local/lib/python3.10/dist-packages/urllib3/connectionpool.py", line 398, in _make_request
2023-06-05 21:57:07     conn.request(method, url, **httplib_request_kw)
2023-06-05 21:57:07   File "/usr/local/lib/python3.10/dist-packages/urllib3/connection.py", line 239, in request
2023-06-05 21:57:07     super(HTTPConnection, self).request(method, url, body=body, headers=headers)
2023-06-05 21:57:07   File "/usr/lib/python3.10/http/client.py", line 1282, in request
2023-06-05 21:57:07     self._send_request(method, url, body, headers, encode_chunked)
2023-06-05 21:57:07   File "/usr/lib/python3.10/http/client.py", line 1328, in _send_request
2023-06-05 21:57:07     self.endheaders(body, encode_chunked=encode_chunked)
2023-06-05 21:57:07   File "/usr/lib/python3.10/http/client.py", line 1277, in endheaders
2023-06-05 21:57:07     self._send_output(message_body, encode_chunked=encode_chunked)
2023-06-05 21:57:07   File "/usr/lib/python3.10/http/client.py", line 1037, in _send_output
2023-06-05 21:57:07     self.send(msg)
2023-06-05 21:57:07   File "/usr/lib/python3.10/http/client.py", line 975, in send
2023-06-05 21:57:07     self.connect()
2023-06-05 21:57:07   File "/usr/local/lib/python3.10/dist-packages/urllib3/connection.py", line 205, in connect
2023-06-05 21:57:07     conn = self._new_conn()
2023-06-05 21:57:07   File "/usr/local/lib/python3.10/dist-packages/urllib3/connection.py", line 186, in _new_conn
2023-06-05 21:57:07     raise NewConnectionError(
2023-06-05 21:57:07 urllib3.exceptions.NewConnectionError: <urllib3.connection.HTTPConnection object at 0x7fd9bdbeb190>: Failed to establish a new connection: [Errno -3] Temporary failure in name resolution
2023-06-05 21:57:07 
2023-06-05 21:57:07 During handling of the above exception, another exception occurred:
2023-06-05 21:57:07 
2023-06-05 21:57:07 Traceback (most recent call last):
2023-06-05 21:57:07   File "/usr/local/lib/python3.10/dist-packages/requests/adapters.py", line 489, in send
2023-06-05 21:57:07     resp = conn.urlopen(
2023-06-05 21:57:07   File "/usr/local/lib/python3.10/dist-packages/urllib3/connectionpool.py", line 787, in urlopen
2023-06-05 21:57:07     retries = retries.increment(
2023-06-05 21:57:07   File "/usr/local/lib/python3.10/dist-packages/urllib3/util/retry.py", line 592, in increment
2023-06-05 21:57:07     raise MaxRetryError(_pool, url, error or ResponseError(cause))
2023-06-05 21:57:07 urllib3.exceptions.MaxRetryError: HTTPConnectionPool(host='service_author', port=8081): Max retries exceeded with url: /authors/1 (Caused by NewConnectionError('<urllib3.connection.HTTPConnection object at 0x7fd9bdbeb190>: Failed to establish a new connection: [Errno -3] Temporary failure in name resolution'))
2023-06-05 21:57:07 
2023-06-05 21:57:07 During handling of the above exception, another exception occurred:
2023-06-05 21:57:07 
2023-06-05 21:57:07 Traceback (most recent call last):
2023-06-05 21:57:07   File "/./service_main.py", line 74, in get_author
2023-06-05 21:57:07     response_author = requests.get("http://" + service_author + "/authors/" + str(id))
2023-06-05 21:57:07   File "/usr/local/lib/python3.10/dist-packages/requests/api.py", line 73, in get
2023-06-05 21:57:07     return request("get", url, params=params, **kwargs)
2023-06-05 21:57:07   File "/usr/local/lib/python3.10/dist-packages/requests/api.py", line 59, in request
2023-06-05 21:57:07     return session.request(method=method, url=url, **kwargs)
2023-06-05 21:57:07   File "/usr/local/lib/python3.10/dist-packages/requests/sessions.py", line 587, in request
2023-06-05 21:57:07     resp = self.send(prep, **send_kwargs)
2023-06-05 21:57:07   File "/usr/local/lib/python3.10/dist-packages/requests/sessions.py", line 701, in send
2023-06-05 21:57:07     r = adapter.send(request, **kwargs)
2023-06-05 21:57:07   File "/usr/local/lib/python3.10/dist-packages/requests/adapters.py", line 565, in send
2023-06-05 21:57:07     raise ConnectionError(e, request=request)
2023-06-05 21:57:07 requests.exceptions.ConnectionError: HTTPConnectionPool(host='service_author', port=8081): Max retries exceeded with url: /authors/1 (Caused by NewConnectionError('<urllib3.connection.HTTPConnection object at 0x7fd9bdbeb190>: Failed to establish a new connection: [Errno -3] Temporary failure in name resolution'))
2023-06-05 21:57:07 
2023-06-05 21:57:07 During handling of the above exception, another exception occurred:
2023-06-05 21:57:07 
2023-06-05 21:57:07 Traceback (most recent call last):
2023-06-05 21:57:07   File "/usr/lib/python3.10/logging/__init__.py", line 1100, in emit
2023-06-05 21:57:07     msg = self.format(record)
2023-06-05 21:57:07   File "/usr/lib/python3.10/logging/__init__.py", line 943, in format
2023-06-05 21:57:07     return fmt.format(record)
2023-06-05 21:57:07   File "/usr/lib/python3.10/logging/__init__.py", line 678, in format
2023-06-05 21:57:07     record.message = record.getMessage()
2023-06-05 21:57:07   File "/usr/lib/python3.10/logging/__init__.py", line 368, in getMessage
2023-06-05 21:57:07     msg = msg % self.args
2023-06-05 21:57:07 TypeError: not all arguments converted during string formatting
2023-06-05 21:57:07 Call stack:
2023-06-05 21:57:07   File "<string>", line 1, in <module>
2023-06-05 21:57:07   File "/usr/lib/python3.10/multiprocessing/spawn.py", line 116, in spawn_main
2023-06-05 21:57:07     exitcode = _main(fd, parent_sentinel)
2023-06-05 21:57:07   File "/usr/lib/python3.10/multiprocessing/spawn.py", line 129, in _main
2023-06-05 21:57:07     return self._bootstrap(parent_sentinel)
2023-06-05 21:57:07   File "/usr/lib/python3.10/multiprocessing/process.py", line 314, in _bootstrap
2023-06-05 21:57:07     self.run()
2023-06-05 21:57:07   File "/usr/lib/python3.10/multiprocessing/process.py", line 108, in run
2023-06-05 21:57:07     self._target(*self._args, **self._kwargs)
2023-06-05 21:57:07   File "/usr/local/lib/python3.10/dist-packages/uvicorn/_subprocess.py", line 76, in subprocess_started
2023-06-05 21:57:07     target(sockets=sockets)
2023-06-05 21:57:07   File "/usr/local/lib/python3.10/dist-packages/uvicorn/server.py", line 60, in run
2023-06-05 21:57:07     return asyncio.run(self.serve(sockets=sockets))
2023-06-05 21:57:07   File "/usr/lib/python3.10/asyncio/runners.py", line 44, in run
2023-06-05 21:57:07     return loop.run_until_complete(main)
2023-06-05 21:57:07   File "/usr/lib/python3.10/asyncio/base_events.py", line 633, in run_until_complete
2023-06-05 21:57:07     self.run_forever()
2023-06-05 21:57:07   File "/usr/lib/python3.10/asyncio/base_events.py", line 600, in run_forever
2023-06-05 21:57:07     self._run_once()
2023-06-05 21:57:07   File "/usr/lib/python3.10/asyncio/base_events.py", line 1896, in _run_once
2023-06-05 21:57:07     handle._run()
2023-06-05 21:57:07   File "/usr/lib/python3.10/asyncio/events.py", line 80, in _run
2023-06-05 21:57:07     self._context.run(self._callback, *self._args)
2023-06-05 21:57:07   File "/usr/local/lib/python3.10/dist-packages/uvicorn/protocols/http/httptools_impl.py", line 419, in run_asgi
2023-06-05 21:57:07     result = await app(  # type: ignore[func-returns-value]
2023-06-05 21:57:07   File "/usr/local/lib/python3.10/dist-packages/uvicorn/middleware/proxy_headers.py", line 78, in __call__
2023-06-05 21:57:07     return await self.app(scope, receive, send)
2023-06-05 21:57:07   File "/usr/local/lib/python3.10/dist-packages/fastapi/applications.py", line 271, in __call__
2023-06-05 21:57:07     await super().__call__(scope, receive, send)
2023-06-05 21:57:07   File "/usr/local/lib/python3.10/dist-packages/starlette/applications.py", line 118, in __call__
2023-06-05 21:57:07     await self.middleware_stack(scope, receive, send)
2023-06-05 21:57:07   File "/usr/local/lib/python3.10/dist-packages/starlette/middleware/errors.py", line 162, in __call__
2023-06-05 21:57:07     await self.app(scope, receive, _send)
2023-06-05 21:57:07   File "/usr/local/lib/python3.10/dist-packages/starlette/middleware/exceptions.py", line 68, in __call__
2023-06-05 21:57:07     await self.app(scope, receive, sender)
2023-06-05 21:57:07   File "/usr/local/lib/python3.10/dist-packages/fastapi/middleware/asyncexitstack.py", line 18, in __call__
2023-06-05 21:57:07     await self.app(scope, receive, send)
2023-06-05 21:57:07   File "/usr/local/lib/python3.10/dist-packages/starlette/routing.py", line 706, in __call__
2023-06-05 21:57:07     await route.handle(scope, receive, send)
2023-06-05 21:57:07   File "/usr/local/lib/python3.10/dist-packages/starlette/routing.py", line 276, in handle
2023-06-05 21:57:07     await self.app(scope, receive, send)
2023-06-05 21:57:07   File "/usr/local/lib/python3.10/dist-packages/starlette/routing.py", line 66, in app
2023-06-05 21:57:07     response = await func(request)
2023-06-05 21:57:07   File "/usr/local/lib/python3.10/dist-packages/fastapi/routing.py", line 237, in app
2023-06-05 21:57:07     raw_response = await run_endpoint_function(
2023-06-05 21:57:07   File "/usr/local/lib/python3.10/dist-packages/fastapi/routing.py", line 163, in run_endpoint_function
2023-06-05 21:57:07     return await dependant.call(**values)
2023-06-05 21:57:07   File "/./service_main.py", line 105, in read_presentation
2023-06-05 21:57:07     author = get_author(presentation.author_id)
2023-06-05 21:57:07   File "/./circuitbreaker.py", line 159, in wrapper
2023-06-05 21:57:07     return call(function, *args, **kwargs)
2023-06-05 21:57:07   File "/./circuitbreaker.py", line 170, in call
2023-06-05 21:57:07     return func(*args, **kwargs)
2023-06-05 21:57:07   File "/./service_main.py", line 76, in get_author
2023-06-05 21:57:07     logging.warning(">>> Error Connecting:", errc)
2023-06-05 21:57:07 Message: '>>> Error Connecting:'
2023-06-05 21:57:07 Arguments: (ConnectionError(MaxRetryError("HTTPConnectionPool(host='service_author', port=8081): Max retries exceeded with url: /authors/1 (Caused by NewConnectionError('<urllib3.connection.HTTPConnection object at 0x7fd9bdbeb190>: Failed to establish a new connection: [Errno -3] Temporary failure in name resolution'))")),)
2023-06-05 21:57:07 WARNING:root:Circuit "get_author" is "open", failures: 5
2023-06-05 21:57:07 WARNING:root:
2023-06-05 21:57:08 WARNING:root:Circuit "get_author" is "open", failures: 5
2023-06-05 21:57:08 WARNING:root:
2023-06-05 21:57:09 WARNING:root:Circuit "get_author" is "open", failures: 5
2023-06-05 21:57:09 WARNING:root:
2023-06-05 21:57:10 WARNING:root:Circuit "get_author" is "open", failures: 5
2023-06-05 21:57:10 WARNING:root:
2023-06-05 21:57:11 WARNING:root:Circuit "get_author" is "open", failures: 5
2023-06-05 21:57:11 WARNING:root:
2023-06-05 21:57:12 WARNING:root:Circuit "get_author" is "open", failures: 5
2023-06-05 21:57:12 WARNING:root:
2023-06-05 21:57:13 WARNING:root:Circuit "get_author" is "open", failures: 5
2023-06-05 21:57:13 WARNING:root:
2023-06-05 21:57:14 WARNING:root:Circuit "get_author" is "open", failures: 5
2023-06-05 21:57:15 WARNING:root:
2023-06-05 21:57:16 WARNING:root:Circuit "get_author" is "open", failures: 5
2023-06-05 21:57:16 WARNING:root:
2023-06-05 21:57:17 WARNING:root:Circuit "get_author" is "half_open", failures: 5
2023-06-05 21:57:17 WARNING:root:
2023-06-05 21:57:18 WARNING:root:Circuit "get_author" is "half_open", failures: 5
2023-06-05 21:57:18 WARNING:root:
2023-06-05 21:57:19 WARNING:root:Circuit "get_author" is "half_open", failures: 5
2023-06-05 21:57:19 WARNING:root:
2023-06-05 21:57:20 WARNING:root:Circuit "get_author" is "half_open", failures: 5
2023-06-05 21:57:20 WARNING:root:
2023-06-05 21:57:21 WARNING:root:Circuit "get_author" is "half_open", failures: 5
2023-06-05 21:57:21 WARNING:root:
2023-06-05 21:57:22 WARNING:root:Circuit "get_author" is "half_open", failures: 5
2023-06-05 21:57:22 WARNING:root:
2023-06-05 21:57:23 WARNING:root:Circuit "get_author" is "half_open", failures: 5
2023-06-05 21:57:23 WARNING:root:
2023-06-05 21:57:24 WARNING:root:Circuit "get_author" is "half_open", failures: 5
2023-06-05 21:57:24 WARNING:root:
2023-06-05 21:57:25 WARNING:root:Circuit "get_author" is "half_open", failures: 5
2023-06-05 21:57:25 WARNING:root:
2023-06-05 21:57:26 WARNING:root:Circuit "get_author" is "half_open", failures: 5
2023-06-05 21:57:27 WARNING:root:
2023-06-05 21:57:28 WARNING:root:Circuit "get_author" is "half_open", failures: 5
2023-06-05 21:57:28 WARNING:root:
2023-06-05 21:57:29 WARNING:root:Circuit "get_author" is "half_open", failures: 5
2023-06-05 21:57:29 WARNING:root:
2023-06-05 21:57:30 WARNING:root:Circuit "get_author" is "half_open", failures: 5
2023-06-05 21:57:30 WARNING:root:
2023-06-05 21:57:31 WARNING:root:Circuit "get_author" is "half_open", failures: 5
2023-06-05 21:57:31 WARNING:root:
2023-06-05 21:57:32 WARNING:root:Circuit "get_author" is "half_open", failures: 5
2023-06-05 21:57:32 WARNING:root:
2023-06-05 21:57:33 WARNING:root:Circuit "get_author" is "half_open", failures: 5
2023-06-05 21:57:33 WARNING:root:
2023-06-05 21:57:34 WARNING:root:Circuit "get_author" is "half_open", failures: 5
2023-06-05 21:57:34 WARNING:root:
2023-06-05 21:57:35 WARNING:root:Circuit "get_author" is "half_open", failures: 5
2023-06-05 21:57:35 WARNING:root:
2023-06-05 21:57:37 WARNING:root:Circuit "get_author" is "half_open", failures: 5
2023-06-05 21:57:37 WARNING:root:
2023-06-05 21:57:38 WARNING:root:Circuit "get_author" is "half_open", failures: 5
2023-06-05 21:57:38 WARNING:root:
2023-06-05 21:57:39 WARNING:root:Circuit "get_author" is "half_open", failures: 5
2023-06-05 21:57:39 WARNING:root:
2023-06-05 21:57:39 --- Logging error ---
2023-06-05 21:57:39 Traceback (most recent call last):
2023-06-05 21:57:39   File "/usr/local/lib/python3.10/dist-packages/urllib3/connection.py", line 174, in _new_conn
2023-06-05 21:57:39     conn = connection.create_connection(
2023-06-05 21:57:39   File "/usr/local/lib/python3.10/dist-packages/urllib3/util/connection.py", line 72, in create_connection
2023-06-05 21:57:39     for res in socket.getaddrinfo(host, port, family, socket.SOCK_STREAM):
2023-06-05 21:57:39   File "/usr/lib/python3.10/socket.py", line 955, in getaddrinfo
2023-06-05 21:57:39     for res in _socket.getaddrinfo(host, port, family, type, proto, flags):
2023-06-05 21:57:39 socket.gaierror: [Errno -3] Temporary failure in name resolution
2023-06-05 21:57:39 
2023-06-05 21:57:39 During handling of the above exception, another exception occurred:
2023-06-05 21:57:39 
2023-06-05 21:57:39 Traceback (most recent call last):
2023-06-05 21:57:39   File "/usr/local/lib/python3.10/dist-packages/urllib3/connectionpool.py", line 703, in urlopen
2023-06-05 21:57:39     httplib_response = self._make_request(
2023-06-05 21:57:39   File "/usr/local/lib/python3.10/dist-packages/urllib3/connectionpool.py", line 398, in _make_request
2023-06-05 21:57:39     conn.request(method, url, **httplib_request_kw)
2023-06-05 21:57:39   File "/usr/local/lib/python3.10/dist-packages/urllib3/connection.py", line 239, in request
2023-06-05 21:57:39     super(HTTPConnection, self).request(method, url, body=body, headers=headers)
2023-06-05 21:57:39   File "/usr/lib/python3.10/http/client.py", line 1282, in request
2023-06-05 21:57:39     self._send_request(method, url, body, headers, encode_chunked)
2023-06-05 21:57:39   File "/usr/lib/python3.10/http/client.py", line 1328, in _send_request
2023-06-05 21:57:39     self.endheaders(body, encode_chunked=encode_chunked)
2023-06-05 21:57:39   File "/usr/lib/python3.10/http/client.py", line 1277, in endheaders
2023-06-05 21:57:39     self._send_output(message_body, encode_chunked=encode_chunked)
2023-06-05 21:57:39   File "/usr/lib/python3.10/http/client.py", line 1037, in _send_output
2023-06-05 21:57:39     self.send(msg)
2023-06-05 21:57:39   File "/usr/lib/python3.10/http/client.py", line 975, in send
2023-06-05 21:57:39     self.connect()
2023-06-05 21:57:39   File "/usr/local/lib/python3.10/dist-packages/urllib3/connection.py", line 205, in connect
2023-06-05 21:57:39     conn = self._new_conn()
2023-06-05 21:57:39   File "/usr/local/lib/python3.10/dist-packages/urllib3/connection.py", line 186, in _new_conn
2023-06-05 21:57:39     raise NewConnectionError(
2023-06-05 21:57:39 urllib3.exceptions.NewConnectionError: <urllib3.connection.HTTPConnection object at 0x7fd9bdbe8040>: Failed to establish a new connection: [Errno -3] Temporary failure in name resolution
2023-06-05 21:57:39 
2023-06-05 21:57:39 During handling of the above exception, another exception occurred:
2023-06-05 21:57:39 
2023-06-05 21:57:39 Traceback (most recent call last):
2023-06-05 21:57:39   File "/usr/local/lib/python3.10/dist-packages/requests/adapters.py", line 489, in send
2023-06-05 21:57:39     resp = conn.urlopen(
2023-06-05 21:57:39   File "/usr/local/lib/python3.10/dist-packages/urllib3/connectionpool.py", line 787, in urlopen
2023-06-05 21:57:39     retries = retries.increment(
2023-06-05 21:57:39   File "/usr/local/lib/python3.10/dist-packages/urllib3/util/retry.py", line 592, in increment
2023-06-05 21:57:39     raise MaxRetryError(_pool, url, error or ResponseError(cause))
2023-06-05 21:57:39 urllib3.exceptions.MaxRetryError: HTTPConnectionPool(host='service_author', port=8081): Max retries exceeded with url: /authors/1 (Caused by NewConnectionError('<urllib3.connection.HTTPConnection object at 0x7fd9bdbe8040>: Failed to establish a new connection: [Errno -3] Temporary failure in name resolution'))
2023-06-05 21:57:39 
2023-06-05 21:57:39 During handling of the above exception, another exception occurred:
2023-06-05 21:57:39 
2023-06-05 21:57:39 Traceback (most recent call last):
2023-06-05 21:57:39   File "/./service_main.py", line 74, in get_author
2023-06-05 21:57:39     response_author = requests.get("http://" + service_author + "/authors/" + str(id))
2023-06-05 21:57:39   File "/usr/local/lib/python3.10/dist-packages/requests/api.py", line 73, in get
2023-06-05 21:57:39     return request("get", url, params=params, **kwargs)
2023-06-05 21:57:39   File "/usr/local/lib/python3.10/dist-packages/requests/api.py", line 59, in request
2023-06-05 21:57:39     return session.request(method=method, url=url, **kwargs)
2023-06-05 21:57:39   File "/usr/local/lib/python3.10/dist-packages/requests/sessions.py", line 587, in request
2023-06-05 21:57:39     resp = self.send(prep, **send_kwargs)
2023-06-05 21:57:39   File "/usr/local/lib/python3.10/dist-packages/requests/sessions.py", line 701, in send
2023-06-05 21:57:39     r = adapter.send(request, **kwargs)
2023-06-05 21:57:39   File "/usr/local/lib/python3.10/dist-packages/requests/adapters.py", line 565, in send
2023-06-05 21:57:39     raise ConnectionError(e, request=request)
2023-06-05 21:57:39 requests.exceptions.ConnectionError: HTTPConnectionPool(host='service_author', port=8081): Max retries exceeded with url: /authors/1 (Caused by NewConnectionError('<urllib3.connection.HTTPConnection object at 0x7fd9bdbe8040>: Failed to establish a new connection: [Errno -3] Temporary failure in name resolution'))
2023-06-05 21:57:39 
2023-06-05 21:57:39 During handling of the above exception, another exception occurred:
2023-06-05 21:57:39 
2023-06-05 21:57:39 Traceback (most recent call last):
2023-06-05 21:57:39   File "/usr/lib/python3.10/logging/__init__.py", line 1100, in emit
2023-06-05 21:57:39     msg = self.format(record)
2023-06-05 21:57:39   File "/usr/lib/python3.10/logging/__init__.py", line 943, in format
2023-06-05 21:57:39     return fmt.format(record)
2023-06-05 21:57:39   File "/usr/lib/python3.10/logging/__init__.py", line 678, in format
2023-06-05 21:57:39     record.message = record.getMessage()
2023-06-05 21:57:39   File "/usr/lib/python3.10/logging/__init__.py", line 368, in getMessage
2023-06-05 21:57:39     msg = msg % self.args
2023-06-05 21:57:39 TypeError: not all arguments converted during string formatting
2023-06-05 21:57:39 Call stack:
2023-06-05 21:57:39   File "<string>", line 1, in <module>
2023-06-05 21:57:39   File "/usr/lib/python3.10/multiprocessing/spawn.py", line 116, in spawn_main
2023-06-05 21:57:39     exitcode = _main(fd, parent_sentinel)
2023-06-05 21:57:39   File "/usr/lib/python3.10/multiprocessing/spawn.py", line 129, in _main
2023-06-05 21:57:39     return self._bootstrap(parent_sentinel)
2023-06-05 21:57:39   File "/usr/lib/python3.10/multiprocessing/process.py", line 314, in _bootstrap
2023-06-05 21:57:39     self.run()
2023-06-05 21:57:39   File "/usr/lib/python3.10/multiprocessing/process.py", line 108, in run
2023-06-05 21:57:39     self._target(*self._args, **self._kwargs)
2023-06-05 21:57:39   File "/usr/local/lib/python3.10/dist-packages/uvicorn/_subprocess.py", line 76, in subprocess_started
2023-06-05 21:57:39     target(sockets=sockets)
2023-06-05 21:57:39   File "/usr/local/lib/python3.10/dist-packages/uvicorn/server.py", line 60, in run
2023-06-05 21:57:39     return asyncio.run(self.serve(sockets=sockets))
2023-06-05 21:57:39   File "/usr/lib/python3.10/asyncio/runners.py", line 44, in run
2023-06-05 21:57:39     return loop.run_until_complete(main)
2023-06-05 21:57:39   File "/usr/lib/python3.10/asyncio/base_events.py", line 633, in run_until_complete
2023-06-05 21:57:39     self.run_forever()
2023-06-05 21:57:39   File "/usr/lib/python3.10/asyncio/base_events.py", line 600, in run_forever
2023-06-05 21:57:39     self._run_once()
2023-06-05 21:57:39   File "/usr/lib/python3.10/asyncio/base_events.py", line 1896, in _run_once
2023-06-05 21:57:39     handle._run()
2023-06-05 21:57:39   File "/usr/lib/python3.10/asyncio/events.py", line 80, in _run
2023-06-05 21:57:39     self._context.run(self._callback, *self._args)
2023-06-05 21:57:39   File "/usr/local/lib/python3.10/dist-packages/uvicorn/protocols/http/httptools_impl.py", line 419, in run_asgi
2023-06-05 21:57:39     result = await app(  # type: ignore[func-returns-value]
2023-06-05 21:57:39   File "/usr/local/lib/python3.10/dist-packages/uvicorn/middleware/proxy_headers.py", line 78, in __call__
2023-06-05 21:57:39     return await self.app(scope, receive, send)
2023-06-05 21:57:39   File "/usr/local/lib/python3.10/dist-packages/fastapi/applications.py", line 271, in __call__
2023-06-05 21:57:39     await super().__call__(scope, receive, send)
2023-06-05 21:57:39   File "/usr/local/lib/python3.10/dist-packages/starlette/applications.py", line 118, in __call__
2023-06-05 21:57:39     await self.middleware_stack(scope, receive, send)
2023-06-05 21:57:39   File "/usr/local/lib/python3.10/dist-packages/starlette/middleware/errors.py", line 162, in __call__
2023-06-05 21:57:39     await self.app(scope, receive, _send)
2023-06-05 21:57:39   File "/usr/local/lib/python3.10/dist-packages/starlette/middleware/exceptions.py", line 68, in __call__
2023-06-05 21:57:39     await self.app(scope, receive, sender)
2023-06-05 21:57:39   File "/usr/local/lib/python3.10/dist-packages/fastapi/middleware/asyncexitstack.py", line 18, in __call__
2023-06-05 21:57:39     await self.app(scope, receive, send)
2023-06-05 21:57:39   File "/usr/local/lib/python3.10/dist-packages/starlette/routing.py", line 706, in __call__
2023-06-05 21:57:39     await route.handle(scope, receive, send)
2023-06-05 21:57:39   File "/usr/local/lib/python3.10/dist-packages/starlette/routing.py", line 276, in handle
2023-06-05 21:57:39     await self.app(scope, receive, send)
2023-06-05 21:57:39   File "/usr/local/lib/python3.10/dist-packages/starlette/routing.py", line 66, in app
2023-06-05 21:57:39     response = await func(request)
2023-06-05 21:57:39   File "/usr/local/lib/python3.10/dist-packages/fastapi/routing.py", line 237, in app
2023-06-05 21:57:39     raw_response = await run_endpoint_function(
2023-06-05 21:57:39   File "/usr/local/lib/python3.10/dist-packages/fastapi/routing.py", line 163, in run_endpoint_function
2023-06-05 21:57:39     return await dependant.call(**values)
2023-06-05 21:57:39   File "/./service_main.py", line 105, in read_presentation
2023-06-05 21:57:39     author = get_author(presentation.author_id)
2023-06-05 21:57:39   File "/./circuitbreaker.py", line 159, in wrapper
2023-06-05 21:57:39     return call(function, *args, **kwargs)
2023-06-05 21:57:39   File "/./circuitbreaker.py", line 170, in call
2023-06-05 21:57:39     return func(*args, **kwargs)
2023-06-05 21:57:39   File "/./service_main.py", line 76, in get_author
2023-06-05 21:57:39     logging.warning(">>> Error Connecting:", errc)
2023-06-05 21:57:39 Message: '>>> Error Connecting:'
2023-06-05 21:57:39 Arguments: (ConnectionError(MaxRetryError("HTTPConnectionPool(host='service_author', port=8081): Max retries exceeded with url: /authors/1 (Caused by NewConnectionError('<urllib3.connection.HTTPConnection object at 0x7fd9bdbe8040>: Failed to establish a new connection: [Errno -3] Temporary failure in name resolution'))")),)
2023-06-05 21:57:39 INFO:     172.18.0.1:43082 - "GET /presentationsAndAuthor/First%20Presentation HTTP/1.1" 500 Internal Server Error
2023-06-05 21:57:40 WARNING:root:Circuit "get_author" is "open", failures: 6
2023-06-05 21:57:40 WARNING:root:
2023-06-05 21:57:41 WARNING:root:Circuit "get_author" is "open", failures: 6
2023-06-05 21:57:41 WARNING:root:
2023-06-05 21:57:42 WARNING:root:Circuit "get_author" is "open", failures: 6
2023-06-05 21:57:42 WARNING:root:
2023-06-05 21:57:44 WARNING:root:Circuit "get_author" is "open", failures: 6
2023-06-05 21:57:44 WARNING:root:
2023-06-05 21:57:45 WARNING:root:Circuit "get_author" is "open", failures: 6
2023-06-05 21:57:45 WARNING:root:
2023-06-05 21:57:46 WARNING:root:Circuit "get_author" is "open", failures: 6
2023-06-05 21:57:47 WARNING:root:
2023-06-05 21:57:48 WARNING:root:Circuit "get_author" is "open", failures: 6
2023-06-05 21:57:48 WARNING:root:
2023-06-05 21:57:49 WARNING:root:Circuit "get_author" is "open", failures: 6
2023-06-05 21:57:49 WARNING:root:
2023-06-05 21:57:50 WARNING:root:Circuit "get_author" is "half_open", failures: 6
2023-06-05 21:57:50 WARNING:root:
2023-06-05 21:57:51 WARNING:root:Circuit "get_author" is "half_open", failures: 6
2023-06-05 21:57:51 WARNING:root:
2023-06-05 21:57:52 WARNING:root:Circuit "get_author" is "half_open", failures: 6
2023-06-05 21:57:52 WARNING:root:
2023-06-05 21:57:53 WARNING:root:Circuit "get_author" is "half_open", failures: 6
2023-06-05 21:57:53 WARNING:root:
2023-06-05 21:57:54 WARNING:root:Circuit "get_author" is "half_open", failures: 6
2023-06-05 21:57:54 WARNING:root:
2023-06-05 21:57:55 WARNING:root:Circuit "get_author" is "half_open", failures: 6
2023-06-05 21:57:55 WARNING:root:
2023-06-05 21:57:56 WARNING:root:Circuit "get_author" is "half_open", failures: 6
2023-06-05 21:57:56 WARNING:root:
2023-06-05 21:57:57 WARNING:root:Circuit "get_author" is "half_open", failures: 6
2023-06-05 21:57:57 WARNING:root:
2023-06-05 21:57:58 WARNING:root:Circuit "get_author" is "half_open", failures: 6
2023-06-05 21:57:58 WARNING:root:
2023-06-05 21:58:01 WARNING:root:Circuit "get_author" is "half_open", failures: 6
2023-06-05 21:58:01 WARNING:root:
2023-06-05 21:58:01 WARNING:root:Circuit "get_author" is "half_open", failures: 6
2023-06-05 21:58:01 WARNING:root:
2023-06-05 21:58:02 WARNING:root:Circuit "get_author" is "half_open", failures: 6
2023-06-05 21:58:02 WARNING:root:
2023-06-05 21:58:03 WARNING:root:Circuit "get_author" is "half_open", failures: 6
2023-06-05 21:58:03 WARNING:root:
2023-06-05 21:58:04 WARNING:root:Circuit "get_author" is "half_open", failures: 6
2023-06-05 21:58:04 WARNING:root:
2023-06-05 21:58:05 WARNING:root:Circuit "get_author" is "half_open", failures: 6
2023-06-05 21:58:05 WARNING:root:
2023-06-05 21:58:08 WARNING:root:Circuit "get_author" is "half_open", failures: 6
2023-06-05 21:58:08 WARNING:root:
2023-06-05 21:58:09 WARNING:root:Circuit "get_author" is "half_open", failures: 6
2023-06-05 21:58:09 WARNING:root:
2023-06-05 21:58:11 WARNING:root:Circuit "get_author" is "half_open", failures: 6
2023-06-05 21:58:13 WARNING:root:
2023-06-05 21:58:13 WARNING:root:Circuit "get_author" is "half_open", failures: 6
2023-06-05 21:58:17 WARNING:root:
2023-06-05 21:58:17 WARNING:root:Circuit "get_author" is "half_open", failures: 6
2023-06-05 21:58:17 WARNING:root:
2023-06-05 21:58:19 WARNING:root:Circuit "get_author" is "half_open", failures: 6
2023-06-05 21:58:19 WARNING:root:
2023-06-05 21:58:19 WARNING:root:Circuit "get_author" is "half_open", failures: 6
2023-06-05 21:58:19 WARNING:root:
2023-06-05 21:58:20 WARNING:root:Circuit "get_author" is "half_open", failures: 6
2023-06-05 21:58:20 WARNING:root:
2023-06-05 21:58:21 WARNING:root:Circuit "get_author" is "half_open", failures: 6
2023-06-05 21:58:21 WARNING:root:
2023-06-05 21:58:23 WARNING:root:Circuit "get_author" is "half_open", failures: 6
2023-06-05 21:58:23 WARNING:root:
2023-06-05 21:58:23 --- Logging error ---
2023-06-05 21:58:23 Traceback (most recent call last):
2023-06-05 21:58:23   File "/usr/local/lib/python3.10/dist-packages/urllib3/connection.py", line 174, in _new_conn
2023-06-05 21:58:23     conn = connection.create_connection(
2023-06-05 21:58:23   File "/usr/local/lib/python3.10/dist-packages/urllib3/util/connection.py", line 95, in create_connection
2023-06-05 21:58:23     raise err
2023-06-05 21:58:23   File "/usr/local/lib/python3.10/dist-packages/urllib3/util/connection.py", line 85, in create_connection
2023-06-05 21:58:23     sock.connect(sa)
2023-06-05 21:58:23 ConnectionRefusedError: [Errno 111] Connection refused
2023-06-05 21:58:23 
2023-06-05 21:58:23 During handling of the above exception, another exception occurred:
2023-06-05 21:58:23 
2023-06-05 21:58:23 Traceback (most recent call last):
2023-06-05 21:58:23   File "/usr/local/lib/python3.10/dist-packages/urllib3/connectionpool.py", line 703, in urlopen
2023-06-05 21:58:23     httplib_response = self._make_request(
2023-06-05 21:58:23   File "/usr/local/lib/python3.10/dist-packages/urllib3/connectionpool.py", line 398, in _make_request
2023-06-05 21:58:23     conn.request(method, url, **httplib_request_kw)
2023-06-05 21:58:23   File "/usr/local/lib/python3.10/dist-packages/urllib3/connection.py", line 239, in request
2023-06-05 21:58:23     super(HTTPConnection, self).request(method, url, body=body, headers=headers)
2023-06-05 21:58:23   File "/usr/lib/python3.10/http/client.py", line 1282, in request
2023-06-05 21:58:23     self._send_request(method, url, body, headers, encode_chunked)
2023-06-05 21:58:23   File "/usr/lib/python3.10/http/client.py", line 1328, in _send_request
2023-06-05 21:58:23     self.endheaders(body, encode_chunked=encode_chunked)
2023-06-05 21:58:23   File "/usr/lib/python3.10/http/client.py", line 1277, in endheaders
2023-06-05 21:58:23     self._send_output(message_body, encode_chunked=encode_chunked)
2023-06-05 21:58:23   File "/usr/lib/python3.10/http/client.py", line 1037, in _send_output
2023-06-05 21:58:23     self.send(msg)
2023-06-05 21:58:23   File "/usr/lib/python3.10/http/client.py", line 975, in send
2023-06-05 21:58:23     self.connect()
2023-06-05 21:58:23   File "/usr/local/lib/python3.10/dist-packages/urllib3/connection.py", line 205, in connect
2023-06-05 21:58:23     conn = self._new_conn()
2023-06-05 21:58:23   File "/usr/local/lib/python3.10/dist-packages/urllib3/connection.py", line 186, in _new_conn
2023-06-05 21:58:23     raise NewConnectionError(
2023-06-05 21:58:23 urllib3.exceptions.NewConnectionError: <urllib3.connection.HTTPConnection object at 0x7fd9bdc10670>: Failed to establish a new connection: [Errno 111] Connection refused
2023-06-05 21:58:23 
2023-06-05 21:58:23 During handling of the above exception, another exception occurred:
2023-06-05 21:58:23 
2023-06-05 21:58:23 Traceback (most recent call last):
2023-06-05 21:58:23   File "/usr/local/lib/python3.10/dist-packages/requests/adapters.py", line 489, in send
2023-06-05 21:58:23     resp = conn.urlopen(
2023-06-05 21:58:23   File "/usr/local/lib/python3.10/dist-packages/urllib3/connectionpool.py", line 787, in urlopen
2023-06-05 21:58:23     retries = retries.increment(
2023-06-05 21:58:23   File "/usr/local/lib/python3.10/dist-packages/urllib3/util/retry.py", line 592, in increment
2023-06-05 21:58:23     raise MaxRetryError(_pool, url, error or ResponseError(cause))
2023-06-05 21:58:23 urllib3.exceptions.MaxRetryError: HTTPConnectionPool(host='service_author', port=8081): Max retries exceeded with url: /authors/1 (Caused by NewConnectionError('<urllib3.connection.HTTPConnection object at 0x7fd9bdc10670>: Failed to establish a new connection: [Errno 111] Connection refused'))
2023-06-05 21:58:23 
2023-06-05 21:58:23 During handling of the above exception, another exception occurred:
2023-06-05 21:58:23 
2023-06-05 21:58:23 Traceback (most recent call last):
2023-06-05 21:58:23   File "/./service_main.py", line 74, in get_author
2023-06-05 21:58:23     response_author = requests.get("http://" + service_author + "/authors/" + str(id))
2023-06-05 21:58:23   File "/usr/local/lib/python3.10/dist-packages/requests/api.py", line 73, in get
2023-06-05 21:58:23     return request("get", url, params=params, **kwargs)
2023-06-05 21:58:23   File "/usr/local/lib/python3.10/dist-packages/requests/api.py", line 59, in request
2023-06-05 21:58:23     return session.request(method=method, url=url, **kwargs)
2023-06-05 21:58:23   File "/usr/local/lib/python3.10/dist-packages/requests/sessions.py", line 587, in request
2023-06-05 21:58:23     resp = self.send(prep, **send_kwargs)
2023-06-05 21:58:23   File "/usr/local/lib/python3.10/dist-packages/requests/sessions.py", line 701, in send
2023-06-05 21:58:23     r = adapter.send(request, **kwargs)
2023-06-05 21:58:23   File "/usr/local/lib/python3.10/dist-packages/requests/adapters.py", line 565, in send
2023-06-05 21:58:23     raise ConnectionError(e, request=request)
2023-06-05 21:58:23 requests.exceptions.ConnectionError: HTTPConnectionPool(host='service_author', port=8081): Max retries exceeded with url: /authors/1 (Caused by NewConnectionError('<urllib3.connection.HTTPConnection object at 0x7fd9bdc10670>: Failed to establish a new connection: [Errno 111] Connection refused'))
2023-06-05 21:58:23 
2023-06-05 21:58:23 During handling of the above exception, another exception occurred:
2023-06-05 21:58:23 
2023-06-05 21:58:23 Traceback (most recent call last):
2023-06-05 21:58:23   File "/usr/lib/python3.10/logging/__init__.py", line 1100, in emit
2023-06-05 21:58:23     msg = self.format(record)
2023-06-05 21:58:23   File "/usr/lib/python3.10/logging/__init__.py", line 943, in format
2023-06-05 21:58:23     return fmt.format(record)
2023-06-05 21:58:23   File "/usr/lib/python3.10/logging/__init__.py", line 678, in format
2023-06-05 21:58:23     record.message = record.getMessage()
2023-06-05 21:58:23   File "/usr/lib/python3.10/logging/__init__.py", line 368, in getMessage
2023-06-05 21:58:23     msg = msg % self.args
2023-06-05 21:58:23 TypeError: not all arguments converted during string formatting
2023-06-05 21:58:23 Call stack:
2023-06-05 21:58:23   File "<string>", line 1, in <module>
2023-06-05 21:58:23   File "/usr/lib/python3.10/multiprocessing/spawn.py", line 116, in spawn_main
2023-06-05 21:58:23     exitcode = _main(fd, parent_sentinel)
2023-06-05 21:58:23   File "/usr/lib/python3.10/multiprocessing/spawn.py", line 129, in _main
2023-06-05 21:58:23     return self._bootstrap(parent_sentinel)
2023-06-05 21:58:23   File "/usr/lib/python3.10/multiprocessing/process.py", line 314, in _bootstrap
2023-06-05 21:58:23     self.run()
2023-06-05 21:58:23   File "/usr/lib/python3.10/multiprocessing/process.py", line 108, in run
2023-06-05 21:58:23     self._target(*self._args, **self._kwargs)
2023-06-05 21:58:23   File "/usr/local/lib/python3.10/dist-packages/uvicorn/_subprocess.py", line 76, in subprocess_started
2023-06-05 21:58:23     target(sockets=sockets)
2023-06-05 21:58:23   File "/usr/local/lib/python3.10/dist-packages/uvicorn/server.py", line 60, in run
2023-06-05 21:58:23     return asyncio.run(self.serve(sockets=sockets))
2023-06-05 21:58:23   File "/usr/lib/python3.10/asyncio/runners.py", line 44, in run
2023-06-05 21:58:23     return loop.run_until_complete(main)
2023-06-05 21:58:23   File "/usr/lib/python3.10/asyncio/base_events.py", line 633, in run_until_complete
2023-06-05 21:58:23     self.run_forever()
2023-06-05 21:58:23   File "/usr/lib/python3.10/asyncio/base_events.py", line 600, in run_forever
2023-06-05 21:58:23     self._run_once()
2023-06-05 21:58:23   File "/usr/lib/python3.10/asyncio/base_events.py", line 1896, in _run_once
2023-06-05 21:58:23     handle._run()
2023-06-05 21:58:23   File "/usr/lib/python3.10/asyncio/events.py", line 80, in _run
2023-06-05 21:58:23     self._context.run(self._callback, *self._args)
2023-06-05 21:58:23   File "/usr/local/lib/python3.10/dist-packages/uvicorn/protocols/http/httptools_impl.py", line 419, in run_asgi
2023-06-05 21:58:23     result = await app(  # type: ignore[func-returns-value]
2023-06-05 21:58:23   File "/usr/local/lib/python3.10/dist-packages/uvicorn/middleware/proxy_headers.py", line 78, in __call__
2023-06-05 21:58:23     return await self.app(scope, receive, send)
2023-06-05 21:58:23   File "/usr/local/lib/python3.10/dist-packages/fastapi/applications.py", line 271, in __call__
2023-06-05 21:58:23     await super().__call__(scope, receive, send)
2023-06-05 21:58:23   File "/usr/local/lib/python3.10/dist-packages/starlette/applications.py", line 118, in __call__
2023-06-05 21:58:23     await self.middleware_stack(scope, receive, send)
2023-06-05 21:58:23   File "/usr/local/lib/python3.10/dist-packages/starlette/middleware/errors.py", line 162, in __call__
2023-06-05 21:58:23     await self.app(scope, receive, _send)
2023-06-05 21:58:23   File "/usr/local/lib/python3.10/dist-packages/starlette/middleware/exceptions.py", line 68, in __call__
2023-06-05 21:58:23     await self.app(scope, receive, sender)
2023-06-05 21:58:23   File "/usr/local/lib/python3.10/dist-packages/fastapi/middleware/asyncexitstack.py", line 18, in __call__
2023-06-05 21:58:23     await self.app(scope, receive, send)
2023-06-05 21:58:23   File "/usr/local/lib/python3.10/dist-packages/starlette/routing.py", line 706, in __call__
2023-06-05 21:58:23     await route.handle(scope, receive, send)
2023-06-05 21:58:23   File "/usr/local/lib/python3.10/dist-packages/starlette/routing.py", line 276, in handle
2023-06-05 21:58:23     await self.app(scope, receive, send)
2023-06-05 21:58:23   File "/usr/local/lib/python3.10/dist-packages/starlette/routing.py", line 66, in app
2023-06-05 21:58:23     response = await func(request)
2023-06-05 21:58:23   File "/usr/local/lib/python3.10/dist-packages/fastapi/routing.py", line 237, in app
2023-06-05 21:58:23     raw_response = await run_endpoint_function(
2023-06-05 21:58:23   File "/usr/local/lib/python3.10/dist-packages/fastapi/routing.py", line 163, in run_endpoint_function
2023-06-05 21:58:23     return await dependant.call(**values)
2023-06-05 21:58:23   File "/./service_main.py", line 105, in read_presentation
2023-06-05 21:58:23     author = get_author(presentation.author_id)
2023-06-05 21:58:23   File "/./circuitbreaker.py", line 159, in wrapper
2023-06-05 21:58:23     return call(function, *args, **kwargs)
2023-06-05 21:58:23   File "/./circuitbreaker.py", line 170, in call
2023-06-05 21:58:23     return func(*args, **kwargs)
2023-06-05 21:58:23   File "/./service_main.py", line 76, in get_author
2023-06-05 21:58:23     logging.warning(">>> Error Connecting:", errc)
2023-06-05 21:58:23 Message: '>>> Error Connecting:'
2023-06-05 21:58:23 Arguments: (ConnectionError(MaxRetryError("HTTPConnectionPool(host='service_author', port=8081): Max retries exceeded with url: /authors/1 (Caused by NewConnectionError('<urllib3.connection.HTTPConnection object at 0x7fd9bdc10670>: Failed to establish a new connection: [Errno 111] Connection refused'))")),)
2023-06-05 21:58:23 INFO:     172.18.0.1:43086 - "GET /presentationsAndAuthor/First%20Presentation HTTP/1.1" 500 Internal Server Error
2023-06-05 21:58:25 WARNING:root:Circuit "get_author" is "open", failures: 7
2023-06-05 21:58:25 WARNING:root:
2023-06-05 21:58:26 WARNING:root:Circuit "get_author" is "open", failures: 7
2023-06-05 21:58:26 WARNING:root:
2023-06-05 21:58:27 WARNING:root:Circuit "get_author" is "open", failures: 7
2023-06-05 21:58:27 WARNING:root:
2023-06-05 21:58:28 WARNING:root:Circuit "get_author" is "open", failures: 7
2023-06-05 21:58:29 WARNING:root:
2023-06-05 21:58:30 WARNING:root:Circuit "get_author" is "open", failures: 7
2023-06-05 21:58:30 WARNING:root:
2023-06-05 21:58:31 WARNING:root:Circuit "get_author" is "open", failures: 7
2023-06-05 21:58:31 WARNING:root:
2023-06-05 21:58:32 WARNING:root:Circuit "get_author" is "open", failures: 7
2023-06-05 21:58:32 WARNING:root:
2023-06-05 21:58:34 WARNING:root:Circuit "get_author" is "half_open", failures: 7
2023-06-05 21:58:34 WARNING:root:
2023-06-05 21:58:35 WARNING:root:Circuit "get_author" is "half_open", failures: 7
2023-06-05 21:58:35 WARNING:root:
2023-06-05 21:58:36 WARNING:root:Circuit "get_author" is "half_open", failures: 7
2023-06-05 21:58:36 WARNING:root:
2023-06-05 21:58:37 WARNING:root:Circuit "get_author" is "half_open", failures: 7
2023-06-05 21:58:37 WARNING:root:
2023-06-05 21:58:38 WARNING:root:Circuit "get_author" is "half_open", failures: 7
2023-06-05 21:58:39 WARNING:root:
2023-06-05 21:58:40 WARNING:root:Circuit "get_author" is "half_open", failures: 7
2023-06-05 21:58:40 WARNING:root:
2023-06-05 21:58:40 Moore
2023-06-05 21:58:40 INFO:     172.18.0.1:43092 - "GET /presentationsAndAuthor/First%20Presentation HTTP/1.1" 200 OK
2023-06-05 21:58:41 WARNING:root:Circuit "get_author" is "closed", failures: 0
2023-06-05 21:58:41 WARNING:root:
2023-06-05 21:58:42 WARNING:root:Circuit "get_author" is "closed", failures: 0
2023-06-05 21:58:42 WARNING:root:
2023-06-05 21:58:43 WARNING:root:Circuit "get_author" is "closed", failures: 0
2023-06-05 21:58:43 WARNING:root:
2023-06-05 21:58:44 WARNING:root:Circuit "get_author" is "closed", failures: 0
2023-06-05 21:58:44 WARNING:root:
2023-06-05 21:58:45 WARNING:root:Circuit "get_author" is "closed", failures: 0
2023-06-05 21:58:45 WARNING:root:
2023-06-05 21:58:46 WARNING:root:Circuit "get_author" is "closed", failures: 0
2023-06-05 21:58:46 WARNING:root:
2023-06-05 21:58:47 WARNING:root:Circuit "get_author" is "closed", failures: 0
2023-06-05 21:58:47 WARNING:root:
2023-06-05 21:58:48 WARNING:root:Circuit "get_author" is "closed", failures: 0
2023-06-05 21:58:48 WARNING:root:
2023-06-05 21:58:49 WARNING:root:Circuit "get_author" is "closed", failures: 0
2023-06-05 21:58:49 WARNING:root:
2023-06-05 21:58:50 WARNING:root:Circuit "get_author" is "closed", failures: 0
2023-06-05 21:58:50 WARNING:root:
2023-06-05 21:58:52 WARNING:root:Circuit "get_author" is "closed", failures: 0
2023-06-05 21:58:52 WARNING:root:
2023-06-05 21:58:53 WARNING:root:Circuit "get_author" is "closed", failures: 0
2023-06-05 21:58:55 WARNING:root:
2023-06-05 21:58:55 WARNING:root:Circuit "get_author" is "closed", failures: 0
2023-06-05 21:58:55 WARNING:root:
2023-06-05 21:58:55 WARNING:root:Circuit "get_author" is "closed", failures: 0
2023-06-05 21:58:55 WARNING:root: